Workbook

Sheet DEVO
G1: S1 | H1: S1 | I1: S1 | J1: S1 | K1: S1 | L1: S1 | M1: S1 | N1: S2 | O1: S2 | P1: S2 | Q1: S2 | R1: S2 | S1: S2 | T1: S2 | U1: S3 | V1: S3 | W1: S3 | X1: S3 | Y1: S3 | Z1: S3 | AA1: S3 | AB1: S4 | AC1: S4 | AD1: S4 | AE1: S4 | AF1: S4 | AG1: S4 | AH1: S4 | AI1: S5 | AJ1: S5 | AK1: S5 | AL1: S5 | AM1: S5 | AN1: S5 | AO1: S5 | AP1: S6 | AQ1: S6 | AR1: S6 | AS1: S6 | AT1: S6 | AU1: S6 | AV1: S6 | AW1: S7 | AX1: S7 | AY1: S7 | AZ1: S7 | BA1: S7 | BB1: S7 | BC1: S7 | BD1: S8 | BE1: S8 | BF1: S8 | BG1: S8 | BH1: S8 | BI1: S8 | BJ1: S8 | BK1: S9 | BL1: S9 | BM1: S9 | BN1: S9 | BO1: S9 | BP1: S9 | BQ1: S9
B2: DEVOCIONAL | G2: JUNIO | P2: JULIO | AU2: AGOSTO
G3: SEMANA 1 | N3: SEMANA 2 | U3: SEMANA 3 | AB3: SEMANA 4 | AI3: SEMANA 5 | AP3: SEMANA 6 | AW3: SEMANA 7 | BD3: SEMANA 8 | BK3: SEMANA 9
C4: TUTOR | D4: NOMBRES | E4: DNI | F4: Fecha Nac. | G4: 46195 | H4: =G4+1 -> 46196 | I4: =H4+1 -> 46197 | J4: =I4+1 -> 46198 | K4: =J4+1 -> 46199 | L4: =K4+1 -> 46200 | M4: =L4+1 -> 46201 | N4: =M4+1 -> 46202 | O4: =N4+1 -> 46203 | ... BQ4: =BP4+1 -> 46257
A5: ='D2'!D4 -> ESC.LID-0209 | B5: 1 | C5: ='D2'!C4 -> AUDI ESTELA SAHUANAY HUISACAYNA | D5: ='D2'!F4 -> ALVA PATRÓN, ISAÍAS SAID | E5: ='D2'!G4 -> 72066954 | F5: 39672 | L5: 1 | O5: 1 | Q5: 1 | V5: 1 | X5: 1 | AD5: 1 | AE5: 1 | AY5: 1
A6: ='D2'!D5 -> ESC.LID-0214 | B6: =1+B5 -> 2 | C6: ='D2'!C5 -> AUDI ESTELA SAHUANAY HUISACAYNA | D6: ='D2'!F5 -> ARANDA HACHER, FELIPE MANUEL | E6: ='D2'!G5 -> 42973857 | F6: 31169
A7: ='D2'!D6 -> ESC.LID-0221 | B7: =1+B6 -> 3 | C7: ='D2'!C6 -> AUDI ESTELA SAHUANAY HUISACAYNA | D7: ='D2'!F6 -> CACERES VARGAS, WILBER ALFREDO | E7: ='D2'!G6 -> 09481596 | F7: 25381
A8: ='D2'!D7 -> ESC.LID-0227 | B8: =1+B7 -> 4 | C8: ='D2'!C7 -> AUDI ESTELA SAHUANAY HUISACAYNA | D8: ='D2'!F7 -> COMENTERO CARREÑO, MAYLY | E8: ='D2'!G7 -> 76057551 | F8: 38334
A9: ='D2'!D8 -> ESC.LID-0233 | B9: =1+B8 -> 5 | C9: ='D2'!C8 -> AUDI ESTELA SAHUANAY HUISACAYNA | D9: ='D2'!F8 -> ECHEVARRIA LINARES, EDISON EDWARD’S | E9: ='D2'!G8 -> 73683815 | F9: 34217 | J9: 1 | K9: 1 | L9: 1 | M9: 1 | N9: 1 | O9: 1 | P9: 1 | Q9: 1 | R9: 1 | S9: 1 | T9: 1 | U9: 1 | V9: 1 | W9: 1 | X9: 1 | Y9: 1 | Z9: 1 | AA9: 1 | AB9: 1 | AC9: 1 | AD9: 1 | AE9: 1 | AF9: 1 | AG9: 1 | AH9: 1 | AP9: 1 | AQ9: 1 | AR9: 1 | AS9: 1 | AT9: 1 | AU9: 1 | AV9: 1 | AW9: 1 | AX9: 1 | AY9: 1 | AZ9: 1 | BA9: 1 | BB9: 1 | BC9: 1
A10: ='D2'!D9 -> ESC.LID-0244 | B10: =1+B9 -> 6 | C10: ='D2'!C9 -> AUDI ESTELA SAHUANAY HUISACAYNA | D10: ='D2'!F9 -> LLAJA TICONA , SAINT | E10: ='D2'!G9 -> 70285329 | F10: 36152 | H10: 1 | I10: 1 | J10: 1 | K10: 1 | L10: 1 | M10: 1 | N10: 1 | O10: 1 | P10: 1 | Q10: 1 | R10: 1 | S10: 1 | T10: 1 | U10: 1 | V10: 1 | W10: 1 | Y10: 1 | AB10: 1 | AC10: 1 | AD10: 1 | AE10: 1 | AF10: 1 | AG10: 1 | AH10: 1 | AL10: 1 | AM10: 1 | AP10: 1 | AQ10: 1 | AR10: 1 | AS10: 1 | AT10: 1 | AU10: 1
A11: ='D2'!D10 -> ESC.LID-0245 | B11: =1+B10 -> 7 | C11: ='D2'!C10 -> AUDI ESTELA SAHUANAY HUISACAYNA | D11: ='D2'!F10 -> LUCAS MELGAREJO, NELY | E11: ='D2'!G10 -> 47715838 | F11: 32030 | G11: 1 | H11: 1 | I11: 1 | J11: 1 | K11: 1 | N11: 1 | O11: 1 | P11: 1 | Q11: 1 | R11: 1 | S11: 1 | T11: 1 | U11: 1 | V11: 1 | W11: 1
A12: ='D2'!D11 -> ESC.LID-0247 | B12: =1+B11 -> 8 | C12: ='D2'!C11 -> AUDI ESTELA SAHUANAY HUISACAYNA | D12: ='D2'!F11 -> MARTELL BARRIOS, ZORAIDA | E12: ='D2'!G11 -> 47773475 | F12: 34099 | G12: 1 | H12: 1 | I12: 1 | J12: 1 | K12: 1 | L12: 1 | M12: 1 | N12: 1 | O12: 1 | P12: 1 | Q12: 1 | R12: 1 | S12: 1 | T12: 1 | U12: 1 | V12: 1 | W12: 1 | X12: 1 | Y12: 1 | Z12: 1 | AA12: 1 | AB12: 1 | AC12: 1 | AD12: 1 | AE12: 1 | AF12: 1 | AG12: 1 | AH12: 1 | AI12: 1 | AJ12: 1 | AK12: 1 | AL12: 1 | AM12: 1 | AN12: 1 | AO12: 1 | AP12: 1 | AQ12: 1 | AR12: 1 | AS12: 1 | AT12: 1 | AU12: 1 | AV12: 1 | AW12: 1 | AX12: 1 | AY12: 1 | AZ12: 1 | BA12: 1 | BB12: 1 | BC12: 1 | BD12: 1 | BE12: 1 | BF12: 1 | BG12: 1 | BH12: 1 | BI12: 1 | BJ12: 1 | BK12: 1 | BL12: 1 | BM12: 1 | BN12: 1
A13: ='D2'!D12 -> ESC.LID-0252 | B13: =1+B12 -> 9 | C13: ='D2'!C12 -> AUDI ESTELA SAHUANAY HUISACAYNA | D13: ='D2'!F12 -> ORTIZ GARCIA, ANTHONY | E13: ='D2'!G12 -> 72192544 | F13: 34964 | G13: 1 | T13: 1
A14: ='D2'!D13 -> ESC.LID-0259 | B14: =1+B13 -> 10 | C14: ='D2'!C13 -> AUDI ESTELA SAHUANAY HUISACAYNA | D14: ='D2'!F13 -> PEREYRA CANCHES, EDGAR DANNY | E14: ='D2'!G13 -> 45715957 | F14: 32591
A15: ='D2'!D14 -> ESC.LID-0266 | B15: =1+B14 -> 11 | C15: ='D2'!C14 -> AUDI ESTELA SAHUANAY HUISACAYNA | D15: ='D2'!F14 -> RAMOS ROJAS, SOCORRO | E15: ='D2'!G14 -> 09334182 | F15: ='D2'!I14
A16: ='D2'!D15 -> ESC.LID-0268 | B16: =1+B15 -> 12 | C16: ='D2'!C15 -> AUDI ESTELA SAHUANAY HUISACAYNA | D16: ='D2'!F15 -> REYES RUIZ, MARIBEL MERCEDES | E16: ='D2'!G15 -> 07245185 | F16: 28247 | G16: 1 | H16: 1 | I16: 1 | J16: 1 | K16: 1 | L16: 1 | M16: 1 | N16: 1 | O16: 1 | P16: 1 | Q16: 1 | R16: 1 | S16: 1 | T16: 1 | U16: 1 | V16: 1 | W16: 1 | X16: 1 | Y16: 1 | Z16: 1 | AA16: 1 | AB16: 1 | AC16: 1 | AD16: 1 | AE16: 1 | AF16: 1 | AG16: 1 | AH16: 1 | AI16: 1 | AJ16: 1 | AK16: 1 | AL16: 1 | AM16: 1 | AN16: 1 | AO16: 1 | AP16: 1 | AQ16: 1 | AR16: 1 | AS16: 1 | AT16: 1 | AU16: 1 | AV16: 1 | AW16: 1 | AX16: 1 | AY16: 1 | AZ16: 1 | BA16: 1 | BB16: 1 | BC16: 1 | BD16: 1 | BE16: 1 | BF16: 1 | BG16: 1 | BH16: 1 | BI16: 1 | BJ16: 1 | BK16: 1 | BL16: 1 | BM16: 1 | BN16: 1
A17: ='D2'!D16 -> ESC.LID-0271 | B17: =1+B16 -> 13 | C17: ='D2'!C16 -> AUDI ESTELA SAHUANAY HUISACAYNA | D17: ='D2'!F16 -> RIVAS ALVAREZ, CARMEN | E17: ='D2'!G16 -> 10214646 | F17: ='D2'!I16 -> 27508
A18: ='D2'!D17 -> ESC.LID-0274 | B18: =1+B17 -> 14 | C18: ='D2'!C17 -> AUDI ESTELA SAHUANAY HUISACAYNA | D18: ='D2'!F17 -> ROJAS MORALES, GIANELLA | E18: ='D2'!G17 -> 74971204 | F18: ='D2'!I17 -> 36820 | AB18: 1
A19: ='D2'!D18 -> ESC.LID-0278 | B19: =1+B18 -> 15 | C19: ='D2'!C18 -> AUDI ESTELA SAHUANAY HUISACAYNA | D19: ='D2'!F18 -> SAGASTEGUI ORIHUELA, ALAN ALBERTO | E19: ='D2'!G18 -> 46373531 | F19: ='D2'!I18 -> 33047
A20: ='D2'!D19 -> ESC.LID-0283 | B20: =1+B19 -> 16 | C20: ='D2'!C19 -> AUDI ESTELA SAHUANAY HUISACAYNA | D20: ='D2'!F19 -> SULCA RODRIGUEZ, DIEGO ARMANDO | E20: ='D2'!G19 -> 46258796 | F20: ='D2'!I19 -> 32907
A21: ='D2'!D20 -> ESC.LID-1450 | B21: =1+B20 -> 17 | C21: ='D2'!C20 -> AUDI ESTELA SAHUANAY HUISACAYNA | D21: ='D2'!F20 -> JORIS ONSIA, MAARTEN | E21: ='D2'!G20 -> 04045579 | F21: 30092 | X21: 1 | Y21: 1 | Z21: 1 | AB21: 1 | AC21: 1 | AD21: 1 | AE21: 1 | AF21: 1 | AG21: 1 | AH21: 1 | AI21: 1 | AJ21: 1 | AK21: 1 | AL21: 1 | AM21: 1 | AN21: 1 | AO21: 1 | AP21: 1 | AQ21: 1 | AR21: 1 | AS21: 1 | AT21: 1 | AU21: 1 | AV21: 1 | AW21: 1 | AX21: 1 | AY21: 1 | AZ21: 1 | BA21: 1 | BB21: 1 | BC21: 1 | BD21: 1 | BE21: 1 | BF21: 1 | BG21: 1 | BH21: 1 | BI21: 1 | BJ21: 1 | BK21: 1 | BL21: 1 | BM21: 1 | BN21: 1
A22: ='D2'!D21 -> ESC.LID-1499 | B22: =1+B21 -> 18 | C22: ='D2'!C21 -> AUDI ESTELA SAHUANAY HUISACAYNA | D22: ='D2'!F21 -> SANCHEZ PEREZ, PAMELA ISABEL | E22: ='D2'!G21 -> 72759143 | F22: ='D2'!I21 | AB22: 1 | AC22: 1 | AD22: 1 | AE22: 1 | AF22: 1 | AG22: 1
A23: ='D2'!D22 -> ESC.LID-1504 | B23: =1+B22 -> 19 | C23: ='D2'!C22 -> AUDI ESTELA SAHUANAY HUISACAYNA | D23: ='D2'!F22 -> COELLO PACHECO, JULIO CESAR | E23: ='D2'!G22 -> 21497420 | F23: ='D2'!I22 | AK23: 1 | AL23: 1 | AM23: 1 | AN23: 1 | AO23: 1 | AP23: 1 | AQ23: 1 | AR23: 1 | AS23: 1 | AT23: 1 | AU23: 1 | AV23: 1 | AW23: 1 | AX23: 1 | AY23: 1 | AZ23: 1 | BA23: 1 | BB23: 1 | BC23: 1 | BD23: 1 | BE23: 1 | BF23: 1 | BG23: 1 | BH23: 1 | BI23: 1 | BJ23: 1 | BK23: 1 | BL23: 1 | BM23: 1 | BN23: 1
A24: ='D2'!D23 | B24: =1+B23 -> 20 | C24: ='D2'!C23 | D24: ='D2'!F23 | E24: ='D2'!G23 | F24: ='D2'!I23
A25: ='D2'!D24 | B25: =1+B24 -> 21 | C25: ='D2'!C24 | D25: ='D2'!F24 | E25: ='D2'!G24 | F25: ='D2'!I24
A26: ='D2'!D25 | B26: =1+B25 -> 22 | C26: ='D2'!C25 | D26: ='D2'!F25 | E26: ='D2'!G25 | F26: ='D2'!I25
A27: ='D2'!D26 | B27: =1+B26 -> 23 | C27: ='D2'!C26 | D27: ='D2'!F26 | E27: ='D2'!G26 | F27: ='D2'!I26
A28: ='D2'!D27 | B28: =1+B27 -> 24 | C28: ='D2'!C27 | D28: ='D2'!F27 | E28: ='D2'!G27 | F28: ='D2'!I27
A29: ='D2'!D28 | B29: =1+B28 -> 25 | C29: ='D2'!C28 | D29: ='D2'!F28 | E29: ='D2'!G28 | F29: ='D2'!I28
A30: ='D2'!D29 | B30: =1+B29 -> 26 | C30: ='D2'!C29 | D30: ='D2'!F29 | E30: ='D2'!G29 | F30: ='D2'!I29
A31: ='D2'!D30 | B31: =1+B30 -> 27 | C31: ='D2'!C30 | D31: ='D2'!F30 | E31: ='D2'!G30 | F31: ='D2'!I30
A32: ='D2'!D31 | B32: =1+B31 -> 28 | C32: ='D2'!C31 | D32: ='D2'!F31 | E32: ='D2'!G31 | F32: ='D2'!I31
A33: ='D2'!D32 | B33: =1+B32 -> 29 | C33: ='D2'!C32 | D33: ='D2'!F32 | E33: ='D2'!G32 | F33: ='D2'!I32
A34: ='D2'!D33 | B34: =1+B33 -> 30 | C34: ='D2'!C33 | D34: ='D2'!F33 | E34: ='D2'!G33 | F34: ='D2'!I33
A35: ='D2'!D34 | B35: =1+B34 -> 31 | C35: ='D2'!C34 | D35: ='D2'!F34 | E35: ='D2'!G34 | F35: ='D2'!I34
... A52: ='D2'!D51 | B52: =1+B51 -> 48 | C52: ='D2'!C51 | D52: ='D2'!F51 | E52: ='D2'!G51 | F52: ='D2'!I51
B53: =1+B52 -> 49 | C53: ='D2'!C52 | D53: ='D2'!F52 | E53: ='D2'!G52 | F53: ='D2'!I52
B54: =1+B53 -> 50 | C54: ='D2'!C53 | D54: ='D2'!F53 | E54: ='D2'!G53 | F54: ='D2'!I53
B55: =1+B54 -> 51 | C55: ='D2'!C54 | D55: ='D2'!F54 | E55: ='D2'!G54 | F55: ='D2'!I54
B56: =1+B55 -> 52 | C56: ='D2'!C55 | D56: ='D2'!F55 | E56: ='D2'!G55 | F56: ='D2'!I55
...

Sheet ASISTENCIA
F1: ASISTENCIA CLASES VIRTUALES | P1: ZOOM Y MEMORIZAR | AU1: SI
F2: SEMANA 1 | G2: SEMANA 2 | H2: SEMANA 3 | I2: SEMANA 4 | J2: SEMANA 5 | K2: SEMANA 6 | L2: SEMANA 7 | M2: SEMANA 8 | N2: SEMANA 9 | P2: Zoom | Q2: Memorizar | R2: Zoom | S2: Memorizar | T2: Zoom | U2: Memorizar | V2: Zoom | W2: Memorizar | X2: Zoom | Y2: Memorizar | Z2: Zoom | AA2: Memorizar | AB2: Zoom | AC2: Memorizar | AD2: Zoom | AE2: Memorizar | AF2: Zoom | AG2: Memorizar | AI2: TRABAJO | AK2: EXAMEN
C3: TUTOR | D3: NOMBRES | E3: DNI | F3: S1 | G3: S2 | H3: S3 | I3: S4 | J3: S5 | K3: S6 | L3: S7 | M3: S8 | N3: S9 | P3: Z1 | Q3: M1 | R3: Z2 | S3: M2 | T3: Z3 | U3: M3 | V3: Z4 | W3: M4 | X3: Z5 | Y3: M5 | Z3: Z6 | AA3: M6 | AB3: Z7 | AC3: M7 | AD3: Z8 | AE3: M8 | AF3: Z9 | AG3: M9 | AI3: T1 | AK3: E1 | AM3: OBSERVACIONES | AN3: Es oyente | AO3: Nombre Lider | AP3: Cell. Lider | AU3: OBSERVACIONES
A4: ='D2'!D4 -> ESC.LID-0209 | B4: 1 | C4: ='D2'!C4 -> AUDI ESTELA SAHUANAY HUISACAYNA | D4: ='D2'!F4 -> ALVA PATRÓN, ISAÍAS SAID | E4: ='D2'!G4 -> 72066954 | F4: 1 | G4: 3 | H4: 2 | I4: 1 | S4: 1 | Y4: 1 | AA4: 1 | AC4: 1 | AE4: 1 | AO4: Daniel Campos | AP4: 913550127 | AU4: 01. ALUMNO - NO DESEA CONTINUAR
A5: ='D2'!D5 -> ESC.LID-0214 | B5: =1+B4 -> 2 | C5: ='D2'!C5 -> AUDI ESTELA SAHUANAY HUISACAYNA | D5: ='D2'!F5 -> ARANDA HACHER, FELIPE MANUEL | E5: ='D2'!G5 -> 42973857 | AM5: No responde el alumno ni el lider | AO5: William Bonifacio | AP5: 981070518 | AU5: 02. ALUMNO - PROBLEMAS PERSONALES
A6: ='D2'!D6 -> ESC.LID-0221 | B6: =1+B5 -> 3 | C6: ='D2'!C6 -> AUDI ESTELA SAHUANAY HUISACAYNA | D6: ='D2'!F6 -> CACERES VARGAS, WILBER ALFREDO | E6: ='D2'!G6 -> 09481596 | AM6: Se converso con su lider , dijo que el alumno está apoyando a su esposa enferma | AO6: Edwin Montano | AP6: 989039557 | AU6: 03. ALUMNO - PROMETE ENVIAR
A7: ='D2'!D7 -> ESC.LID-0227 | B7: =1+B6 -> 4 | C7: ='D2'!C7 -> AUDI ESTELA SAHUANAY HUISACAYNA | D7: ='D2'!F7 -> COMENTERO CARREÑO, MAYLY | E7: ='D2'!G7 -> 76057551 | F7: 1 | G7: 4 | H7: 3 | I7: 1 | J7: 3 | K7: 1 | L7: 1 | M7: 2 | N7: 2 | S7: 1 | W7: 1 | Y7: 1 | AA7: 1 | AC7: 1 | AE7: 1 | AG7: 1 | AI7: 0 | AK7: 20 | AM7: El trabajo no es del libro, ni un libro cristiano, ni una apreciación de clase. | AO7: Miriam | AP7: 976312280 | AU7: 04. ALUMNO - PROMETE ENVIAR PERO NADA
A8: ='D2'!D8 -> ESC.LID-0233 | B8: =1+B7 -> 5 | C8: ='D2'!C8 -> AUDI ESTELA SAHUANAY HUISACAYNA | D8: ='D2'!F8 -> ECHEVARRIA LINARES, EDISON EDWARD’S | E8: ='D2'!G8 -> 73683815 | F8: 1 | G8: 1 | I8: 1 | J8: 2 | K8: 1 | L8: 1 | M8: 1 | N8: 2 | S8: 1 | AE8: 1 | AG8: 1 | AI8: 13 | AK8: 20 | AO8: William Bonifacio | AP8: 981070518 | AU8: 05. ALUMNO - NO SABIA QUE ESTABA MATRICULADO (se informara a Lider)
A9: ='D2'!D9 -> ESC.LID-0244 | B9: =1+B8 -> 6 | C9: ='D2'!C9 -> AUDI ESTELA SAHUANAY HUISACAYNA | D9: ='D2'!F9 -> LLAJA TICONA , SAINT | E9: ='D2'!G9 -> 70285329 | F9: 1 | G9: 1 | H9: 1 | I9: 1 | J9: 1 | K9: 1 | L9: 1 | M9: 1 | N9: 1 | Q9: 2 | U9: 1 | W9: 1 | Y9: 1 | AA9: 1 | AC9: 1 | AE9: 1 | AG9: 1 | AI9: 8 | AK9: 20 | AM9: Presentó un .txt hecho con IA | AO9: Jhon | AP9: 969312062 | AU9: 06. ALUMNO - MENOR DE EDAD (se informara lider para apoyo)
A10: ='D2'!D10 -> ESC.LID-0245 | B10: =1+B9 -> 7 | C10: ='D2'!C10 -> AUDI ESTELA SAHUANAY HUISACAYNA | D10: ='D2'!F10 -> LUCAS MELGAREJO, NELY | E10: ='D2'!G10 -> 47715838 | F10: 1 | G10: 4 | H10: 4 | I10: 4 | J10: 1 | K10: 1 | L10: 1 | M10: 1 | N10: 1 | R10: 2 | S10: 1 | U10: 2 | V10: 5 | W10: 1 | Y10: 1 | AA10: 1 | AC10: 1 | AI10: 12 | AO10: Lucy Guerrero | AP10: 975537169 | AU10: 07. CELULAR - APAGADO/MALOGRADO/EQUIVOCADO
A11: ='D2'!D11 -> ESC.LID-0247 | B11: =1+B10 -> 8 | C11: ='D2'!C11 -> AUDI ESTELA SAHUANAY HUISACAYNA | D11: ='D2'!F11 -> MARTELL BARRIOS, ZORAIDA | E11: ='D2'!G11 -> 47773475 | F11: 4 | G11: 4 | H11: 4 | I11: 4 | J11: 4 | K11: 4 | L11: 3 | M11: 3 | N11: 4 | Q11: 2 | S11: 1 | U11: 1 | W11: 1 | Y11: 1 | AA11: 1 | AC11: 1 | AE11: 2 | AI11: 10 | AK11: 20 | AM11: El trabajo está hecho con IA | AO11: Katerine Salas | AP11: 950198680 | AU11: 08. CELULAR - TIMBRA Y NO CONTESTA
A12: ='D2'!D12 -> ESC.LID-0252 | B12: =1+B11 -> 9 | C12: ='D2'!C12 -> AUDI ESTELA SAHUANAY HUISACAYNA | D12: ='D2'!F12 -> ORTIZ GARCIA, ANTHONY | E12: ='D2'!G12 -> 72192544 | F12: 4 | G12: 1 | J12: 1 | K12: 1 | L12: 1 | M12: 1 | N12: 1 | Q12: 2 | S12: 1 | Y12: 1 | AA12: 1 | AC12: 1 | AE12: 1 | AG12: 1 | AI12: 13 | AK12: 12 | AO12: Jaime Zegarra | AP12: 923877478 | AU12: 09. CELULAR - WHATSAPP DEJA EN VISTO
A13: ='D2'!D13 -> ESC.LID-0259 | B13: =1+B12 -> 10 | C13: ='D2'!C13 -> AUDI ESTELA SAHUANAY HUISACAYNA | D13: ='D2'!F13 -> PEREYRA CANCHES, EDGAR DANNY | E13: ='D2'!G13 -> 45715957 | F13: 1 | G13: 3 | H13: 3 | I13: 4 | J13: 3 | K13: 1 | L13: 1 | M13: 1 | N13: 1 | S13: 1 | U13: 1 | W13: 1 | Y13: 1 | AA13: 1 | AC13: 1 | AE13: 1 | AG13: 1 | AI13: 13 | AK13: 20 | AO13: Carlos González | AP13: 997622122 | AU13: 10. CELULAR - WHATSAPP SE LE LLAMA Y NO CONTESTA
A14: ='D2'!D14 -> ESC.LID-0266 | B14: =1+B13 -> 11 | C14: ='D2'!C14 -> AUDI ESTELA SAHUANAY HUISACAYNA | D14: ='D2'!F14 -> RAMOS ROJAS, SOCORRO | E14: ='D2'!G14 -> 09334182 | AM14: No responde, solo dice "Gracias" y no contesta cuando se le llama | AU14: 11. ESTUDIOS - NO TIENE TIEMPO
A15: ='D2'!D15 -> ESC.LID-0268 | B15: =1+B14 -> 12 | C15: ='D2'!C15 -> AUDI ESTELA SAHUANAY HUISACAYNA | D15: ='D2'!F15 -> REYES RUIZ, MARIBEL MERCEDES | E15: ='D2'!G15 -> 07245185 | F15: 4 | G15: 4 | H15: 4 | I15: 4 | J15: 4 | K15: 1 | L15: 1 | M15: 1 | N15: 3 | Q15: 2 | R15: 2 | S15: 2 | U15: 2 | W15: 1 | Y15: 2 | AA15: 2 | AC15: 2 | AE15: 2 | AG15: 2 | AI15: 19 | AK15: 20 | AO15: Katerine Salas | AP15: 950198680 | AU15: 12. ESTUDIOS - ESTA EN EXAMENES
A16: ='D2'!D16 -> ESC.LID-0271 | B16: =1+B15 -> 13 | C16: ='D2'!C16 -> AUDI ESTELA SAHUANAY HUISACAYNA | D16: ='D2'!F16 -> RIVAS ALVAREZ, CARMEN | E16: ='D2'!G16 -> 10214646 | F16: 1 | G16: 1 | H16: 1 | AO16: Janet López Escobar | AP16: 961852035 | AU16: 13. IGLESIA - SE FUE A OTRA SEDE
A17: ='D2'!D17 -> ESC.LID-0274 | B17: =1+B16 -> 14 | C17: ='D2'!C17 -> AUDI ESTELA SAHUANAY HUISACAYNA | D17: ='D2'!F17 -> ROJAS MORALES, GIANELLA | E17: ='D2'!G17 -> 74971204 | AM17: No contesta, deja en visto | AO17: Luz Bravo | AP17: 919526320 | AU17: 14. IGLESIA - SE RETIRO
A18: ='D2'!D18 -> ESC.LID-0278 | B18: =1+B17 -> 15 | C18: ='D2'!C18 -> AUDI ESTELA SAHUANAY HUISACAYNA | D18: ='D2'!F18 -> SAGASTEGUI ORIHUELA, ALAN ALBERTO | E18: ='D2'!G18 -> 46373531 | F18: 1 | G18: 1 | H18: 1 | I18: 1 | J18: 1 | K18: 1 | L18: 1 | M18: 1 | N18: 3 | Q18: 2 | AI18: 13 | AK18: 16 | AO18: Juan Vasquez | AP18: 991047608 | AU18: 15. IGLESIA - SE FUE A OTRO CURSO
A19: ='D2'!D19 -> ESC.LID-0283 | B19: =1+B18 -> 16 | C19: ='D2'!C19 -> AUDI ESTELA SAHUANAY HUISACAYNA | D19: ='D2'!F19 -> SULCA RODRIGUEZ, DIEGO ARMANDO | E19: ='D2'!G19 -> 46258796 | F19: 1 | Q19: 2 | S19: 1 | U19: 1 | W19: 2 | Y19: 1 | AA19: 1 | AC19: 1 | AE19: 1 | AM19: Se le envía los audios, pero no responde cuando se le pide las clases | AN19: SI | AO19: Jean Franco Vasquez | AP19: 998172190 | AU19: 16. LIDER - APOYANDO A SU DISC.
A20: ='D2'!D20 -> ESC.LID-1450 | B20: =1+B19 -> 17 | C20: ='D2'!C20 -> AUDI ESTELA SAHUANAY HUISACAYNA | D20: ='D2'!F20 -> JORIS ONSIA, MAARTEN | E20: ='D2'!G20 -> 04045579 | G20: 1 | H20: 1 | I20: 2 | J20: 3 | K20: 1 | L20: 2 | M20: 3 | N20: 2 | V20: 5 | AI20: 15 | AK20: 20 | AO20: William Bonifacio | AP20: 981070518 | AU20: 17. LIDER - DICE QUE NO LE CONTESTA
A21: ='D2'!D21 -> ESC.LID-1499 | B21: =1+B20 -> 18 | C21: ='D2'!C21 -> AUDI ESTELA SAHUANAY HUISACAYNA | D21: ='D2'!F21 -> SANCHEZ PEREZ, PAMELA ISABEL | E21: ='D2'!G21 -> 72759143 | F21: 1 | I21: 4 | J21: 5 | K21: 4 | L21: 1 | M21: 1 | N21: 1 | Y21: 2 | AI21: 13 | AK21: 20 | AM21: Está estudiando y trabajando y no tiene tiempo | AO21: Katerine Salas | AP21: 950198680 | AU21: 18. LIDER - PROMETE HABLAR CON SU DISC.
A22: ='D2'!D22 -> ESC.LID-1504 | B22: =1+B21 -> 19 | C22: ='D2'!C22 -> AUDI ESTELA SAHUANAY HUISACAYNA | D22: ='D2'!F22 -> COELLO PACHECO, JULIO CESAR | E22: ='D2'!G22 -> 21497420 | I22: 1 | J22: 1 | K22: 2 | L22: 1 | M22: 1 | N22: 2 | V22: 5 | W22: 1 | Y22: 2 | AA22: 2 | AC22: 2 | AE22: 2 | AG22: 2 | AI22: 11 | AK22: 20 | AM22: El trabajo no es del libro, es una monografía sobre la soledad. | AO22: Henry Quiroz | AP22: 959480317 | AU22: 19. OYENTE - ESPERANDO RPTA. LIDER
A23: ='D2'!D23 | B23: =1+B22 -> 20 | C23: ='D2'!C23 | D23: ='D2'!F23 | E23: ='D2'!G23 | AU23: 20. OYENTE - LIDER NO RESPONDE
A24: ='D2'!D24 | B24: =1+B23 -> 21 | C24: ='D2'!C24 | D24: ='D2'!F24 | E24: ='D2'!G24 | AU24: 21. SALUD - ALUMNO ENFERMO
A25: ='D2'!D25 | B25: =1+B24 -> 22 | C25: ='D2'!C25 | D25: ='D2'!F25 | E25: ='D2'!G25 | AU25: 22. SALUD - EMBARAZO
A26: ='D2'!D26 | B26: =1+B25 -> 23 | C26: ='D2'!C26 | D26: ='D2'!F26 | E26: ='D2'!G26 | AU26: 23. SALUD - FAMILIAR ENFERMO
A27: ='D2'!D27 | B27: =1+B26 -> 24 | C27: ='D2'!C27 | D27: ='D2'!F27 | E27: ='D2'!G27 | AU27: 24. SALUD - HOSPITALIZADO/ACCIDENTADO
A28: ='D2'!D28 | B28: =1+B27 -> 25 | C28: ='D2'!C28 | D28: ='D2'!F28 | E28: ='D2'!G28 | AU28: 25. SALUD - LUTO
A29: ='D2'!D29 | B29: =1+B28 -> 26 | C29: ='D2'!C29 | D29: ='D2'!F29 | E29: ='D2'!G29 | AU29: 26. TRABAJO - NO TIENE TIEMPO
A30: ='D2'!D30 | B30: =1+B29 -> 27 | C30: ='D2'!C30 | D30: ='D2'!F30 | E30: ='D2'!G30 | AU30: 27. TRABAJO - PROVINCIA/EXTRANJERO
A31: ='D2'!D31 | B31: =1+B30 -> 28 | C31: ='D2'!C31 | D31: ='D2'!F31 | E31: ='D2'!G31
A32: ='D2'!D32 | B32: =1+B31 -> 29 | C32: ='D2'!C32 | D32: ='D2'!F32 | E32: ='D2'!G32
A33: ='D2'!D33 | B33: =1+B32 -> 30 | C33: ='D2'!C33 | D33: ='D2'!F33 | E33: ='D2'!G33
A34: ='D2'!D34 | B34: =1+B33 -> 31 | C34: ='D2'!C34 | D34: ='D2'!F34 | E34: ='D2'!G34
A35: ='D2'!D35 | B35: =1+B34 -> 32 | C35: ='D2'!C35 | D35: ='D2'!F35 | E35: ='D2'!G35
A36: ='D2'!D36 | B36: =1+B35 -> 33 | C36: ='D2'!C36 | D36: ='D2'!F36 | E36: ='D2'!G36
A37: ='D2'!D37 | B37: =1+B36 -> 34 | C37: ='D2'!C37 | D37: ='D2'!F37 | E37: ='D2'!G37
A38: ='D2'!D38 | B38: =1+B37 -> 35 | C38: ='D2'!C38 | D38: ='D2'!F38 | E38: ='D2'!G38
A39: ='D2'!D39 | B39: =1+B38 -> 36 | C39: ='D2'!C39 | D39: ='D2'!F39 | E39: ='D2'!G39
A40: ='D2'!D40 | B40: =1+B39 -> 37 | C40: ='D2'!C40 | D40: ='D2'!F40 | E40: ='D2'!G40
...

Sheet D2
A1: 5 | B1: =IFERROR(__xludf.DUMMYFUNCTION("QUERY(IMPORTRANGE($F$1,""Hoja1!A8:D47""),""Select Col3,Col4 where Col1=""&A1&"""")"),"ANTIOQUIANOS") -> ANTIOQUIANOS | C1: =IFERROR(__xludf.DUMMYFUNCTION("""COMPUTED_VALUE"""),"AUDI ESTELA SAHUANAY HUISACAYNA") -> AUDI ESTELA SAHUANAY HUISACAYNA | F1: 1AoYstZNHHVYHovopoDScSPeXriWKbKp9iByxtjEjal4 | L1: S1 | M1: Z1 | N1: M1 | O1: =ASISTENCIA!$F$66 -> 46201 | P1: S2 | Q1: Z2 | R1: M2 | S1: =ASISTENCIA!$G$66 -> 46208 | T1: S3 | U1: Z3 | V1: M3 | W1: =ASISTENCIA!$H$66 -> 46215 | X1: S4 | Y1: Z4 | Z1: M4 | AA1: =ASISTENCIA!$I$66 -> 46222 | AB1: S5 | AC1: Z5 | AD1: M5 | AE1: =ASISTENCIA!$J$66 -> 46229 | AF1: S6 | AG1: Z6 | AH1: M6 | AI1: =ASISTENCIA!$K$66 -> 46236 | AJ1: S7 | AK1: Z7 | AL1: M7 | AM1: =ASISTENCIA!$L$66 -> 46243 | AN1: S8 | AO1: Z8 | AP1: M8 | AQ1: =ASISTENCIA!$M$66 -> 46250 | AR1: S9 | AS1: Z9 | AT1: M9 | AU1: =ASISTENCIA!$N$66 -> 46257 | AV1: T1 | AW1: E1 | BJ1: =IFERROR(__xludf.DUMMYFUNCTION("IMPORTRANGE($F$1,""Hoja1!B61:E62"")"),0.0) -> 0 | BK1: =IFERROR(__xludf.DUMMYFUNCTION("""COMPUTED_VALUE"""),0.0) -> 0 | BL1: =IFERROR(__xludf.DUMMYFUNCTION("""COMPUTED_VALUE"""),0.0) -> 0 | BM1: =IFERROR(__xludf.DUMMYFUNCTION("""COMPUTED_VALUE"""),1.0) -> 1 | BS1: OBSERVACIONES | BT1: Nombre Lider | BU1: Cell. Lider | BV1: Es oyente
B2: DATOS DE INSCRIPCION | L2: CLASE 1 | P2: CLASE 2 | T2: CLASE 3 | X2: CLASE 4 | AB2: CLASE 5 | AF2: CLASE 6 | AJ2: CLASE 7 | AN2: CLASE 8 | AR2: CLASE 9 | AV2: TRABAJO | AW2: EXAMEN | BJ2: =IFERROR(__xludf.DUMMYFUNCTION("""COMPUTED_VALUE"""),9.0) -> 9
B3: EQUIPO | C3: COTUTOR | D3: ORDEN | E3: Grupo | F3: Alumno | G3: DocId | H3: Celular | I3: Fecha Nac. | J3: Fecha Nac. | K3: Fecha Nac. | L3: A | M3: Z | N3: M | O3: D | P3: A | Q3: Z | R3: M | S3: D | T3: A | U3: Z | V3: M | W3: D | X3: A | Y3: Z | Z3: M | AA3: D | AB3: A | AC3: Z | AD3: M | AE3: D | AF3: A | AG3: Z | AH3: M | AI3: D | AJ3: A | AK3: Z | AL3: M | AM3: D | AN3: A | AO3: Z | AP3: M | AQ3: D | AR3: A | AS3: Z | AT3: M | AU3: D | AY3: A1 | AZ3: A2 | BA3: A3 | BB3: A4 | BC3: A5 | BD3: A6 | BE3: A7 | BF3: A8 | BG3: A9 | BH3: PROMEDIO | BI3: RANKING | BJ3: D1 | BK3: D2 | BL3: D3 | BM3: D4 | BN3: D5 | BO3: D6 | BP3: D7 | BQ3: D8 | BR3: D9 | BX3: =IFERROR(__xludf.DUMMYFUNCTION("IMPORTRANGE($F$1,""Hoja1!B120:C139"")"),"") | BY3: =IFERROR(__xludf.DUMMYFUNCTION("""COMPUTED_VALUE"""),"ASISTENCIA") -> ASISTENCIA
A4: 1 | B4: =IFERROR(__xludf.DUMMYFUNCTION("QUERY(IMPORTRANGE($F$1,""Hoja1!G3:Q""),""Select Col1,Col2,Col3,Col4,Col6,Col7,Col8,Col11 where Col1='""&B1&""' and Col2='""&C1&""' ORDER BY Col2 ASC"",0)"),"ANTIOQUIANOS") -> ANTIOQUIANOS | C4: =IFERROR(__xludf.DUMMYFUNCTION("""COMPUTED_VALUE"""),"AUDI ESTELA SAHUANAY HUISACAYNA") -> AUDI ESTELA SAHUANAY HUISACAYNA | D4: =IFERROR(__xludf.DUMMYFUNCTION("""COMPUTED_VALUE"""),"ESC.LID-0209") -> ESC.LID-0209 | E4: =IFERROR(__xludf.DUMMYFUNCTION("""COMPUTED_VALUE"""),"C1131") -> C1131 | F4: =IFERROR(__xludf.DUMMYFUNCTION("""COMPUTED_VALUE"""),"ALVA PATRÓN, ISAÍAS SAID") -> ALVA PATRÓN, ISAÍAS SAID | G4: =IFERROR(__xludf.DUMMYFUNCTION("""COMPUTED_VALUE"""),"72066954") -> 72066954 | H4: =IFERROR(__xludf.DUMMYFUNCTION("""COMPUTED_VALUE"""),"922118392") -> 922118392 | J4: =DEVO!F5 -> 39672 | K4: =IF(I4>0,I4,J4) -> 39672 | L4: =IF(TODAY()>=$O$1-6,SUM(OFFSET(ASISTENCIA!$E$1,MATCH($G4,ASISTENCIA!$E:$E,0)-1,MATCH(L$1,ASISTENCIA!$3:$3,0)-5,1,1)),"") -> 1 | M4: =OFFSET(ASISTENCIA!$E$1,MATCH($G4,ASISTENCIA!$E:$E,0)-1,MATCH(M$1,ASISTENCIA!$3:$3,0)-5,1,1) | N4: =OFFSET(ASISTENCIA!$E$1,MATCH($G4,ASISTENCIA!$E:$E,0)-1,MATCH(N$1,ASISTENCIA!$3:$3,0)-5,1,1) | O4: =IF(TODAY()>=$O$1-6,SUM(OFFSET(DEVO!$F$1,MATCH($G4,DEVO!$E:$E,0)-1,MATCH(L$1,DEVO!$1:$1,0)-6,1,7)),"") -> 1 | P4: =IF(TODAY()>=$S$1-6,SUM(OFFSET(ASISTENCIA!$E$1,MATCH($G4,ASISTENCIA!$E:$E,0)-1,MATCH(P$1,ASISTENCIA!$3:$3,0)-5,1,1)),"") -> 3 | Q4: =OFFSET(ASISTENCIA!$E$1,MATCH($G4,ASISTENCIA!$E:$E,0)-1,MATCH(Q$1,ASISTENCIA!$3:$3,0)-5,1,1) | R4: =OFFSET(ASISTENCIA!$E$1,MATCH($G4,ASISTENCIA!$E:$E,0)-1,MATCH(R$1,ASISTENCIA!$3:$3,0)-5,1,1) -> 1 | S4: =IF(TODAY()>=$S$1-6,SUM(OFFSET(DEVO!$F$1,MATCH($G4,DEVO!$E:$E,0)-1,MATCH(P$1,DEVO!$1:$1,0)-6,1,7)),"") -> 2 | T4: =IF(TODAY()>=$W$1-6,SUM(OFFSET(ASISTENCIA!$E$1,MATCH($G4,ASISTENCIA!$E:$E,0)-1,MATCH(T$1,ASISTENCIA!$3:$3,0)-5,1,1)),"") -> 2 | U4: =OFFSET(ASISTENCIA!$E$1,MATCH($G4,ASISTENCIA!$E:$E,0)-1,MATCH(U$1,ASISTENCIA!$3:$3,0)-5,1,1) | V4: =OFFSET(ASISTENCIA!$E$1,MATCH($G4,ASISTENCIA!$E:$E,0)-1,MATCH(V$1,ASISTENCIA!$3:$3,0)-5,1,1) | W4: =IF(TODAY()>=$W$1-6,SUM(OFFSET(DEVO!$F$1,MATCH($G4,DEVO!$E:$E,0)-1,MATCH(T$1,DEVO!$1:$1,0)-6,1,7)),"") -> 2 | X4: =IF(TODAY()>=$AA$1-6,SUM(OFFSET(ASISTENCIA!$E$1,MATCH($G4,ASISTENCIA!$E:$E,0)-1,MATCH(X$1,ASISTENCIA!$3:$3,0)-5,1,1)),"") -> 1 | Y4: =OFFSET(ASISTENCIA!$E$1,MATCH($G4,ASISTENCIA!$E:$E,0)-1,MATCH(Y$1,ASISTENCIA!$3:$3,0)-5,1,1) | Z4: =OFFSET(ASISTENCIA!$E$1,MATCH($G4,ASISTENCIA!$E:$E,0)-1,MATCH(Z$1,ASISTENCIA!$3:$3,0)-5,1,1) | AA4: =IF(TODAY()>=$AA$1-6,SUM(OFFSET(DEVO!$F$1,MATCH($G4,DEVO!$E:$E,0)-1,MATCH(X$1,DEVO!$1:$1,0)-6,1,7)),"") -> 2 | AB4: =IF(TODAY()>=$AE$1-6,SUM(OFFSET(ASISTENCIA!$E$1,MATCH($G4,ASISTENCIA!$E:$E,0)-1,MATCH(AB$1,ASISTENCIA!$3:$3,0)-5,1,1)),"") -> 0 | AC4: =OFFSET(ASISTENCIA!$E$1,MATCH($G4,ASISTENCIA!$E:$E,0)-1,MATCH(AC$1,ASISTENCIA!$3:$3,0)-5,1,1) | AD4: =OFFSET(ASISTENCIA!$E$1,MATCH($G4,ASISTENCIA!$E:$E,0)-1,MATCH(AD$1,ASISTENCIA!$3:$3,0)-5,1,1) -> 1 | AE4: =IF(TODAY()>=$AE$1-6,SUM(OFFSET(DEVO!$F$1,MATCH($G4,DEVO!$E:$E,0)-1,MATCH(AB$1,DEVO!$1:$1,0)-6,1,7)),"") -> 0 | AF4: =IF(TODAY()>=$AI$1-6,SUM(OFFSET(ASISTENCIA!$E$1,MATCH($G4,ASISTENCIA!$E:$E,0)-1,MATCH(AF$1,ASISTENCIA!$3:$3,0)-5,1,1)),"") -> 0 | AG4: =OFFSET(ASISTENCIA!$E$1,MATCH($G4,ASISTENCIA!$E:$E,0)-1,MATCH(AG$1,ASISTENCIA!$3:$3,0)-5,1,1) | AH4: =OFFSET(ASISTENCIA!$E$1,MATCH($G4,ASISTENCIA!$E:$E,0)-1,MATCH(AH$1,ASISTENCIA!$3:$3,0)-5,1,1) -> 1 | AI4: =IF(TODAY()>=$AI$1-6,SUM(OFFSET(DEVO!$F$1,MATCH($G4,DEVO!$E:$E,0)-1,MATCH(AF$1,DEVO!$1:$1,0)-6,1,7)),"") -> 0 | AJ4: =IF(TODAY()>=$AM$1-6,SUM(OFFSET(ASISTENCIA!$E$1,MATCH($G4,ASISTENCIA!$E:$E,0)-1,MATCH(AJ$1,ASISTENCIA!$3:$3,0)-5,1,1)),"") -> 0 | AK4: =OFFSET(ASISTENCIA!$E$1,MATCH($G4,ASISTENCIA!$E:$E,0)-1,MATCH(AK$1,ASISTENCIA!$3:$3,0)-5,1,1) | AL4: =OFFSET(ASISTENCIA!$E$1,MATCH($G4,ASISTENCIA!$E:$E,0)-1,MATCH(AL$1,ASISTENCIA!$3:$3,0)-5,1,1) -> 1 | AM4: =IF(TODAY()>=$AM$1-6,SUM(OFFSET(DEVO!$F$1,MATCH($G4,DEVO!$E:$E,0)-1,MATCH(AJ$1,DEVO!$1:$1,0)-6,1,7)),"") -> 1 | AN4: =IF(TODAY()>=$AQ$1-6,SUM(OFFSET(ASISTENCIA!$E$1,MATCH($G4,ASISTENCIA!$E:$E,0)-1,MATCH(AN$1,ASISTENCIA!$3:$3,0)-5,1,1)),"") -> 0 | AO4: =OFFSET(ASISTENCIA!$E$1,MATCH($G4,ASISTENCIA!$E:$E,0)-1,MATCH(AO$1,ASISTENCIA!$3:$3,0)-5,1,1) | AP4: =OFFSET(ASISTENCIA!$E$1,MATCH($G4,ASISTENCIA!$E:$E,0)-1,MATCH(AP$1,ASISTENCIA!$3:$3,0)-5,1,1) -> 1 | AQ4: =IF(TODAY()>=$AQ$1-6,SUM(OFFSET(DEVO!$F$1,MATCH($G4,DEVO!$E:$E,0)-1,MATCH(AN$1,DEVO!$1:$1,0)-6,1,7)),"") -> 0 | AR4: =IF(TODAY()>=$AU$1-6,SUM(OFFSET(ASISTENCIA!$E$1,MATCH($G4,ASISTENCIA!$E:$E,0)-1,MATCH(AR$1,ASISTENCIA!$3:$3,0)-5,1,1)),"") -> 0 | AS4: =OFFSET(ASISTENCIA!$E$1,MATCH($G4,ASISTENCIA!$E:$E,0)-1,MATCH(AS$1,ASISTENCIA!$3:$3,0)-5,1,1) | AT4: =OFFSET(ASISTENCIA!$E$1,MATCH($G4,ASISTENCIA!$E:$E,0)-1,MATCH(AT$1,ASISTENCIA!$3:$3,0)-5,1,1) | AU4: =IF(TODAY()>=$AU$1-6,SUM(OFFSET(DEVO!$F$1,MATCH($G4,DEVO!$E:$E,0)-1,MATCH(AR$1,DEVO!$1:$1,0)-6,1,7)),"") -> 0 | AV4: =OFFSET(ASISTENCIA!$E$1,MATCH($G4,ASISTENCIA!$E:$E,0)-1,MATCH(AV$1,ASISTENCIA!$3:$3,0)-5,1,1) | AW4: =OFFSET(ASISTENCIA!$E$1,MATCH($G4,ASISTENCIA!$E:$E,0)-1,MATCH(AW$1,ASISTENCIA!$3:$3,0)-5,1,1) | AY4: =IF(TODAY()>=$O$1-6,COUNTIF(L4,">"&0)," ") -> 1 | AZ4: =IF(TODAY()>=$S$1-6,COUNTIF(P4,">"&0)," ") -> 1 | BA4: =IF(TODAY()>=$W$1-6,COUNTIF(T4,">"&0)," ") -> 1 | BB4: =IF(TODAY()>=$AA$1-6,COUNTIF(X4,">"&0)," ") -> 1 | BC4: =IF(TODAY()>=$AE$1-6,COUNTIF(AB4,">"&0)," ") -> 0 | BD4: =IF(TODAY()>=$AI$1-6,COUNTIF(AF4,">"&0)," ") -> 0 | BE4: =IF(TODAY()>=$AM$1-6,COUNTIF(AJ4,">"&0)," ") -> 0 | BF4: =IF(TODAY()>=$AQ$1-6,COUNTIF(AN4,">"&0)," ") -> 0 | BG4: =IF(TODAY()>=$AU$1-6,COUNTIF(AR4,">"&0)," ") -> 0 | BH4: =IFERROR(SUM(AY4:BG4)/$BJ$2,0)*10 -> 4.4444444 | BI4: =VLOOKUP(BH4,$BX$4:$BY$11,2,1) -> OBSERVADOS | BJ4: =IF(TODAY()>=$O$1-6,VLOOKUP(10*SUMPRODUCT($BJ$1:$BM$1,L4:O4)/MIN((TODAY()-$O$1+7),7),$BX$15:$BY$22,2,1)," ") -> OBSERVADOS | BK4: =IF(TODAY()>=$S$1-6,VLOOKUP(10*SUMPRODUCT($BJ$1:$BM$1,P4:S4)/MIN((TODAY()-$S$1+7),7),$BX$15:$BY$22,2,1)," ") -> OBSERVADOS | BL4: =IF(TODAY()>=$W$1-6,VLOOKUP(10*SUMPRODUCT($BJ$1:$BM$1,T4:W4)/MIN((TODAY()-$W$1+7),7),$BX$15:$BY$22,2,1)," ") -> OBSERVADOS | BM4: =IF(TODAY()>=$AA$1-6,VLOOKUP(10*SUMPRODUCT($BJ$1:$BM$1,X4:AA4)/MIN((TODAY()-$AA$1+7),7),$BX$15:$BY$22,2,1)," ") -> OBSERVADOS | BN4: =IF(TODAY()>=$AE$1-6,VLOOKUP(10*SUMPRODUCT($BJ$1:$BM$1,AB4:AE4)/MIN((TODAY()-$AE$1+7),7),$BX$15:$BY$22,2,1)," ") -> OBSERVADOS | BO4: =IF(TODAY()>=$AI$1-6,VLOOKUP(10*SUMPRODUCT($BJ$1:$BM$1,AF4:AI4)/MIN((TODAY()-$AI$1+7),7),$BX$15:$BY$22,2,1)," ") -> OBSERVADOS | BP4: =IF(TODAY()>=$AM$1-6,VLOOKUP(10*SUMPRODUCT($BJ$1:$BM$1,AJ4:AM4)/MIN((TODAY()-$AM$1+7),7),$BX$15:$BY$22,2,1)," ") -> OBSERVADOS | BQ4: =IF(TODAY()>=$AQ$1-6,VLOOKUP(10*SUMPRODUCT($BJ$1:$BM$1,AN4:AQ4)/MIN((TODAY()-$AQ$1+7),7),$BX$15:$BY$22,2,1)," ") -> OBSERVADOS | BR4: =IF(TODAY()>=$AU$1-6,VLOOKUP(10*SUMPRODUCT($BJ$1:$BM$1,AR4:AU4)/MIN((TODAY()-$AU$1+7),7),$BX$15:$BY$22,2,1)," ") -> OBSERVADOS | BS4: =OFFSET(ASISTENCIA!$E$1,MATCH($G4,ASISTENCIA!$E:$E,0)-1,MATCH(BS$1,ASISTENCIA!$3:$3,0)-5,1,1) | BT4: =OFFSET(ASISTENCIA!$E$1,MATCH($G4,ASISTENCIA!$E:$E,0)-1,MATCH(BT$1,ASISTENCIA!$3:$3,0)-5,1,1) -> Daniel Campos | BU4: =OFFSET(ASISTENCIA!$E$1,MATCH($G4,ASISTENCIA!$E:$E,0)-1,MATCH(BU$1,ASISTENCIA!$3:$3,0)-5,1,1) -> 913550127 | BV4: =OFFSET(ASISTENCIA!$E$1,MATCH($G4,ASISTENCIA!$E:$E,0)-1,MATCH(BV$1,ASISTENCIA!$3:$3,0)-5,1,1) | BX4: =IFERROR(__xludf.DUMMYFUNCTION("""COMPUTED_VALUE"""),0.0) -> 0 | BY4: =IFERROR(__xludf.DUMMYFUNCTION("""COMPUTED_VALUE"""),"OBSERVADOS") -> OBSERVADOS
A5: =1+A4 -> 2 | B5: =IFERROR(__xludf.DUMMYFUNCTION("""COMPUTED_VALUE"""),"ANTIOQUIANOS") -> ANTIOQUIANOS | C5: =IFERROR(__xludf.DUMMYFUNCTION("""COMPUTED_VALUE"""),"AUDI ESTELA SAHUANAY HUISACAYNA") -> AUDI ESTELA SAHUANAY HUISACAYNA | D5: =IFERROR(__xludf.DUMMYFUNCTION("""COMPUTED_VALUE"""),"ESC.LID-0214") -> ESC.LID-0214 | E5: =IFERROR(__xludf.DUMMYFUNCTION("""COMPUTED_VALUE"""),"C1133") -> C1133 | F5: =IFERROR(__xludf.DUMMYFUNCTION("""COMPUTED_VALUE"""),"ARANDA HACHER, FELIPE MANUEL") -> ARANDA HACHER, FELIPE MANUEL | G5: =IFERROR(__xludf.DUMMYFUNCTION("""COMPUTED_VALUE"""),"42973857") -> 42973857 | H5: =IFERROR(__xludf.DUMMYFUNCTION("""COMPUTED_VALUE"""),"928606678") -> 928606678 | J5: =DEVO!F6 -> 31169 | K5: =IF(I5>0,I5,J5) -> 31169 | L5: =IF(TODAY()>=$O$1-6,SUM(OFFSET(ASISTENCIA!$E$1,MATCH($G5,ASISTENCIA!$E:$E,0)-1,MATCH(L$1,ASISTENCIA!$3:$3,0)-5,1,1)),"") -> 0 | M5: =OFFSET(ASISTENCIA!$E$1,MATCH($G5,ASISTENCIA!$E:$E,0)-1,MATCH(M$1,ASISTENCIA!$3:$3,0)-5,1,1) | N5: =OFFSET(ASISTENCIA!$E$1,MATCH($G5,ASISTENCIA!$E:$E,0)-1,MATCH(N$1,ASISTENCIA!$3:$3,0)-5,1,1) | O5: =IF(TODAY()>=$O$1-6,SUM(OFFSET(DEVO!$F$1,MATCH($G5,DEVO!$E:$E,0)-1,MATCH(L$1,DEVO!$1:$1,0)-6,1,7)),"") -> 0 | P5: =IF(TODAY()>=$S$1-6,SUM(OFFSET(ASISTENCIA!$E$1,MATCH($G5,ASISTENCIA!$E:$E,0)-1,MATCH(P$1,ASISTENCIA!$3:$3,0)-5,1,1)),"") -> 0 | Q5: =OFFSET(ASISTENCIA!$E$1,MATCH($G5,ASISTENCIA!$E:$E,0)-1,MATCH(Q$1,ASISTENCIA!$3:$3,0)-5,1,1) | R5: =OFFSET(ASISTENCIA!$E$1,MATCH($G5,ASISTENCIA!$E:$E,0)-1,MATCH(R$1,ASISTENCIA!$3:$3,0)-5,1,1) | S5: =IF(TODAY()>=$S$1-6,SUM(OFFSET(DEVO!$F$1,MATCH($G5,DEVO!$E:$E,0)-1,MATCH(P$1,DEVO!$1:$1,0)-6,1,7)),"") -> 0 | T5: =IF(TODAY()>=$W$1-6,SUM(OFFSET(ASISTENCIA!$E$1,MATCH($G5,ASISTENCIA!$E:$E,0)-1,MATCH(T$1,ASISTENCIA!$3:$3,0)-5,1,1)),"") -> 0 | U5: =OFFSET(ASISTENCIA!$E$1,MATCH($G5,ASISTENCIA!$E:$E,0)-1,MATCH(U$1,ASISTENCIA!$3:$3,0)-5,1,1) | V5: =OFFSET(ASISTENCIA!$E$1,MATCH($G5,ASISTENCIA!$E:$E,0)-1,MATCH(V$1,ASISTENCIA!$3:$3,0)-5,1,1) | W5: =IF(TODAY()>=$W$1-6,SUM(OFFSET(DEVO!$F$1,MATCH($G5,DEVO!$E:$E,0)-1,MATCH(T$1,DEVO!$1:$1,0)-6,1,7)),"") -> 0 | X5: =IF(TODAY()>=$AA$1-6,SUM(OFFSET(ASISTENCIA!$E$1,MATCH($G5,ASISTENCIA!$E:$E,0)-1,MATCH(X$1,ASISTENCIA!$3:$3,0)-5,1,1)),"") -> 0 | Y5: =OFFSET(ASISTENCIA!$E$1,MATCH($G5,ASISTENCIA!$E:$E,0)-1,MATCH(Y$1,ASISTENCIA!$3:$3,0)-5,1,1) | Z5: =OFFSET(ASISTENCIA!$E$1,MATCH($G5,ASISTENCIA!$E:$E,0)-1,MATCH(Z$1,ASISTENCIA!$3:$3,0)-5,1,1) | AA5: =IF(TODAY()>=$AA$1-6,SUM(OFFSET(DEVO!$F$1,MATCH($G5,DEVO!$E:$E,0)-1,MATCH(X$1,DEVO!$1:$1,0)-6,1,7)),"") -> 0 | AB5: =IF(TODAY()>=$AE$1-6,SUM(OFFSET(ASISTENCIA!$E$1,MATCH($G5,ASISTENCIA!$E:$E,0)-1,MATCH(AB$1,ASISTENCIA!$3:$3,0)-5,1,1)),"") -> 0 | AC5: =OFFSET(ASISTENCIA!$E$1,MATCH($G5,ASISTENCIA!$E:$E,0)-1,MATCH(AC$1,ASISTENCIA!$3:$3,0)-5,1,1) | AD5: =OFFSET(ASISTENCIA!$E$1,MATCH($G5,ASISTENCIA!$E:$E,0)-1,MATCH(AD$1,ASISTENCIA!$3:$3,0)-5,1,1) | AE5: =IF(TODAY()>=$AE$1-6,SUM(OFFSET(DEVO!$F$1,MATCH($G5,DEVO!$E:$E,0)-1,MATCH(AB$1,DEVO!$1:$1,0)-6,1,7)),"") -> 0 | AF5: =IF(TODAY()>=$AI$1-6,SUM(OFFSET(ASISTENCIA!$E$1,MATCH($G5,ASISTENCIA!$E:$E,0)-1,MATCH(AF$1,ASISTENCIA!$3:$3,0)-5,1,1)),"") -> 0 | AG5: =OFFSET(ASISTENCIA!$E$1,MATCH($G5,ASISTENCIA!$E:$E,0)-1,MATCH(AG$1,ASISTENCIA!$3:$3,0)-5,1,1) | AH5: =OFFSET(ASISTENCIA!$E$1,MATCH($G5,ASISTENCIA!$E:$E,0)-1,MATCH(AH$1,ASISTENCIA!$3:$3,0)-5,1,1) | AI5: =IF(TODAY()>=$AI$1-6,SUM(OFFSET(DEVO!$F$1,MATCH($G5,DEVO!$E:$E,0)-1,MATCH(AF$1,DEVO!$1:$1,0)-6,1,7)),"") -> 0 | AJ5: =IF(TODAY()>=$AM$1-6,SUM(OFFSET(ASISTENCIA!$E$1,MATCH($G5,ASISTENCIA!$E:$E,0)-1,MATCH(AJ$1,ASISTENCIA!$3:$3,0)-5,1,1)),"") -> 0 | AK5: =OFFSET(ASISTENCIA!$E$1,MATCH($G5,ASISTENCIA!$E:$E,0)-1,MATCH(AK$1,ASISTENCIA!$3:$3,0)-5,1,1) | AL5: =OFFSET(ASISTENCIA!$E$1,MATCH($G5,ASISTENCIA!$E:$E,0)-1,MATCH(AL$1,ASISTENCIA!$3:$3,0)-5,1,1) | AM5: =IF(TODAY()>=$AM$1-6,SUM(OFFSET(DEVO!$F$1,MATCH($G5,DEVO!$E:$E,0)-1,MATCH(AJ$1,DEVO!$1:$1,0)-6,1,7)),"") -> 0 | AN5: =IF(TODAY()>=$AQ$1-6,SUM(OFFSET(ASISTENCIA!$E$1,MATCH($G5,ASISTENCIA!$E:$E,0)-1,MATCH(AN$1,ASISTENCIA!$3:$3,0)-5,1,1)),"") -> 0 | AO5: =OFFSET(ASISTENCIA!$E$1,MATCH($G5,ASISTENCIA!$E:$E,0)-1,MATCH(AO$1,ASISTENCIA!$3:$3,0)-5,1,1) | AP5: =OFFSET(ASISTENCIA!$E$1,MATCH($G5,ASISTENCIA!$E:$E,0)-1,MATCH(AP$1,ASISTENCIA!$3:$3,0)-5,1,1) | AQ5: =IF(TODAY()>=$AQ$1-6,SUM(OFFSET(DEVO!$F$1,MATCH($G5,DEVO!$E:$E,0)-1,MATCH(AN$1,DEVO!$1:$1,0)-6,1,7)),"") -> 0 | AR5: =IF(TODAY()>=$AU$1-6,SUM(OFFSET(ASISTENCIA!$E$1,MATCH($G5,ASISTENCIA!$E:$E,0)-1,MATCH(AR$1,ASISTENCIA!$3:$3,0)-5,1,1)),"") -> 0 | AS5: =OFFSET(ASISTENCIA!$E$1,MATCH($G5,ASISTENCIA!$E:$E,0)-1,MATCH(AS$1,ASISTENCIA!$3:$3,0)-5,1,1) | AT5: =OFFSET(ASISTENCIA!$E$1,MATCH($G5,ASISTENCIA!$E:$E,0)-1,MATCH(AT$1,ASISTENCIA!$3:$3,0)-5,1,1) | AU5: =IF(TODAY()>=$AU$1-6,SUM(OFFSET(DEVO!$F$1,MATCH($G5,DEVO!$E:$E,0)-1,MATCH(AR$1,DEVO!$1:$1,0)-6,1,7)),"") -> 0 | AV5: =OFFSET(ASISTENCIA!$E$1,MATCH($G5,ASISTENCIA!$E:$E,0)-1,MATCH(AV$1,ASISTENCIA!$3:$3,0)-5,1,1) | AW5: =OFFSET(ASISTENCIA!$E$1,MATCH($G5,ASISTENCIA!$E:$E,0)-1,MATCH(AW$1,ASISTENCIA!$3:$3,0)-5,1,1) | AY5: =IF(TODAY()>=$O$1-6,COUNTIF(L5,">"&0)," ") -> 0 | AZ5: =IF(TODAY()>=$S$1-6,COUNTIF(P5,">"&0)," ") -> 0 | BA5: =IF(TODAY()>=$W$1-6,COUNTIF(T5,">"&0)," ") -> 0 | BB5: =IF(TODAY()>=$AA$1-6,COUNTIF(X5,">"&0)," ") -> 0 | BC5: =IF(TODAY()>=$AE$1-6,COUNTIF(AB5,">"&0)," ") -> 0 | BD5: =IF(TODAY()>=$AI$1-6,COUNTIF(AF5,">"&0)," ") -> 0 | BE5: =IF(TODAY()>=$AM$1-6,COUNTIF(AJ5,">"&0)," ") -> 0 | BF5: =IF(TODAY()>=$AQ$1-6,COUNTIF(AN5,">"&0)," ") -> 0 | BG5: =IF(TODAY()>=$AU$1-6,COUNTIF(AR5,">"&0)," ") -> 0 | BH5: =IFERROR(SUM(AY5:BG5)/$BJ$2,0)*10 -> 0 | BI5: =VLOOKUP(BH5,$BX$4:$BY$11,2,1) -> OBSERVADOS | BJ5: =IF(TODAY()>=$O$1-6,VLOOKUP(10*SUMPRODUCT($BJ$1:$BM$1,L5:O5)/MIN((TODAY()-$O$1+7),7),$BX$15:$BY$22,2,1)," ") -> OBSERVADOS | BK5: =IF(TODAY()>=$S$1-6,VLOOKUP(10*SUMPRODUCT($BJ$1:$BM$1,P5:S5)/MIN((TODAY()-$S$1+7),7),$BX$15:$BY$22,2,1)," ") -> OBSERVADOS | BL5: =IF(TODAY()>=$W$1-6,VLOOKUP(10*SUMPRODUCT($BJ$1:$BM$1,T5:W5)/MIN((TODAY()-$W$1+7),7),$BX$15:$BY$22,2,1)," ") -> OBSERVADOS | BM5: =IF(TODAY()>=$AA$1-6,VLOOKUP(10*SUMPRODUCT($BJ$1:$BM$1,X5:AA5)/MIN((TODAY()-$AA$1+7),7),$BX$15:$BY$22,2,1)," ") -> OBSERVADOS | BN5: =IF(TODAY()>=$AE$1-6,VLOOKUP(10*SUMPRODUCT($BJ$1:$BM$1,AB5:AE5)/MIN((TODAY()-$AE$1+7),7),$BX$15:$BY$22,2,1)," ") -> OBSERVADOS | BO5: =IF(TODAY()>=$AI$1-6,VLOOKUP(10*SUMPRODUCT($BJ$1:$BM$1,AF5:AI5)/MIN((TODAY()-$AI$1+7),7),$BX$15:$BY$22,2,1)," ") -> OBSERVADOS | BP5: =IF(TODAY()>=$AM$1-6,VLOOKUP(10*SUMPRODUCT($BJ$1:$BM$1,AJ5:AM5)/MIN((TODAY()-$AM$1+7),7),$BX$15:$BY$22,2,1)," ") -> OBSERVADOS | BQ5: =IF(TODAY()>=$AQ$1-6,VLOOKUP(10*SUMPRODUCT($BJ$1:$BM$1,AN5:AQ5)/MIN((TODAY()-$AQ$1+7),7),$BX$15:$BY$22,2,1)," ") -> OBSERVADOS | BR5: =IF(TODAY()>=$AU$1-6,VLOOKUP(10*SUMPRODUCT($BJ$1:$BM$1,AR5:AU5)/MIN((TODAY()-$AU$1+7),7),$BX$15:$BY$22,2,1)," ") -> OBSERVADOS | BS5: =OFFSET(ASISTENCIA!$E$1,MATCH($G5,ASISTENCIA!$E:$E,0)-1,MATCH(BS$1,ASISTENCIA!$3:$3,0)-5,1,1) -> No responde el alumno ni el lider | BT5: =OFFSET(ASISTENCIA!$E$1,MATCH($G5,ASISTENCIA!$E:$E,0)-1,MATCH(BT$1,ASISTENCIA!$3:$3,0)-5,1,1) -> William Bonifacio | BU5: =OFFSET(ASISTENCIA!$E$1,MATCH($G5,ASISTENCIA!$E:$E,0)-1,MATCH(BU$1,ASISTENCIA!$3:$3,0)-5,1,1) -> 981070518 | BV5: =OFFSET(ASISTENCIA!$E$1,MATCH($G5,ASISTENCIA!$E:$E,0)-1,MATCH(BV$1,ASISTENCIA!$3:$3,0)-5,1,1) | BX5: =IFERROR(__xludf.DUMMYFUNCTION("""COMPUTED_VALUE"""),6.111111111111112) -> 6.1111111 | BY5: =IFERROR(__xludf.DUMMYFUNCTION("""COMPUTED_VALUE"""),"OBSERVADOS") -> OBSERVADOS
A6: =1+A5 -> 3 | B6: =IFERROR(__xludf.DUMMYFUNCTION("""COMPUTED_VALUE"""),"ANTIOQUIANOS") -> ANTIOQUIANOS | C6: =IFERROR(__xludf.DUMMYFUNCTION("""COMPUTED_VALUE"""),"AUDI ESTELA SAHUANAY HUISACAYNA") -> AUDI ESTELA SAHUANAY HUISACAYNA | D6: =IFERROR(__xludf.DUMMYFUNCTION("""COMPUTED_VALUE"""),"ESC.LID-0221") -> ESC.LID-0221 | E6: =IFERROR(__xludf.DUMMYFUNCTION("""COMPUTED_VALUE"""),"C117") -> C117 | F6: =IFERROR(__xludf.DUMMYFUNCTION("""COMPUTED_VALUE"""),"CACERES VARGAS, WILBER ALFREDO") -> CACERES VARGAS, WILBER ALFREDO | G6: =IFERROR(__xludf.DUMMYFUNCTION("""COMPUTED_VALUE"""),"09481596") -> 09481596 | H6: =IFERROR(__xludf.DUMMYFUNCTION("""COMPUTED_VALUE"""),"962943845") -> 962943845 | J6: =DEVO!F7 -> 25381 | K6: =IF(I6>0,I6,J6) -> 25381 | L6: =IF(TODAY()>=$O$1-6,SUM(OFFSET(ASISTENCIA!$E$1,MATCH($G6,ASISTENCIA!$E:$E,0)-1,MATCH(L$1,ASISTENCIA!$3:$3,0)-5,1,1)),"") -> 0 | M6: =OFFSET(ASISTENCIA!$E$1,MATCH($G6,ASISTENCIA!$E:$E,0)-1,MATCH(M$1,ASISTENCIA!$3:$3,0)-5,1,1) | N6: =OFFSET(ASISTENCIA!$E$1,MATCH($G6,ASISTENCIA!$E:$E,0)-1,MATCH(N$1,ASISTENCIA!$3:$3,0)-5,1,1) | O6: =IF(TODAY()>=$O$1-6,SUM(OFFSET(DEVO!$F$1,MATCH($G6,DEVO!$E:$E,0)-1,MATCH(L$1,DEVO!$1:$1,0)-6,1,7)),"") -> 0 | P6: =IF(TODAY()>=$S$1-6,SUM(OFFSET(ASISTENCIA!$E$1,MATCH($G6,ASISTENCIA!$E:$E,0)-1,MATCH(P$1,ASISTENCIA!$3:$3,0)-5,1,1)),"") -> 0 | Q6: =OFFSET(ASISTENCIA!$E$1,MATCH($G6,ASISTENCIA!$E:$E,0)-1,MATCH(Q$1,ASISTENCIA!$3:$3,0)-5,1,1) | R6: =OFFSET(ASISTENCIA!$E$1,MATCH($G6,ASISTENCIA!$E:$E,0)-1,MATCH(R$1,ASISTENCIA!$3:$3,0)-5,1,1) | S6: =IF(TODAY()>=$S$1-6,SUM(OFFSET(DEVO!$F$1,MATCH($G6,DEVO!$E:$E,0)-1,MATCH(P$1,DEVO!$1:$1,0)-6,1,7)),"") -> 0 | T6: =IF(TODAY()>=$W$1-6,SUM(OFFSET(ASISTENCIA!$E$1,MATCH($G6,ASISTENCIA!$E:$E,0)-1,MATCH(T$1,ASISTENCIA!$3:$3,0)-5,1,1)),"") -> 0 | U6: =OFFSET(ASISTENCIA!$E$1,MATCH($G6,ASISTENCIA!$E:$E,0)-1,MATCH(U$1,ASISTENCIA!$3:$3,0)-5,1,1) | V6: =OFFSET(ASISTENCIA!$E$1,MATCH($G6,ASISTENCIA!$E:$E,0)-1,MATCH(V$1,ASISTENCIA!$3:$3,0)-5,1,1) | W6: =IF(TODAY()>=$W$1-6,SUM(OFFSET(DEVO!$F$1,MATCH($G6,DEVO!$E:$E,0)-1,MATCH(T$1,DEVO!$1:$1,0)-6,1,7)),"") -> 0 | X6: =IF(TODAY()>=$AA$1-6,SUM(OFFSET(ASISTENCIA!$E$1,MATCH($G6,ASISTENCIA!$E:$E,0)-1,MATCH(X$1,ASISTENCIA!$3:$3,0)-5,1,1)),"") -> 0 | Y6: =OFFSET(ASISTENCIA!$E$1,MATCH($G6,ASISTENCIA!$E:$E,0)-1,MATCH(Y$1,ASISTENCIA!$3:$3,0)-5,1,1) | Z6: =OFFSET(ASISTENCIA!$E$1,MATCH($G6,ASISTENCIA!$E:$E,0)-1,MATCH(Z$1,ASISTENCIA!$3:$3,0)-5,1,1) | AA6: =IF(TODAY()>=$AA$1-6,SUM(OFFSET(DEVO!$F$1,MATCH($G6,DEVO!$E:$E,0)-1,MATCH(X$1,DEVO!$1:$1,0)-6,1,7)),"") -> 0 | AB6: =IF(TODAY()>=$AE$1-6,SUM(OFFSET(ASISTENCIA!$E$1,MATCH($G6,ASISTENCIA!$E:$E,0)-1,MATCH(AB$1,ASISTENCIA!$3:$3,0)-5,1,1)),"") -> 0 | AC6: =OFFSET(ASISTENCIA!$E$1,MATCH($G6,ASISTENCIA!$E:$E,0)-1,MATCH(AC$1,ASISTENCIA!$3:$3,0)-5,1,1) | AD6: =OFFSET(ASISTENCIA!$E$1,MATCH($G6,ASISTENCIA!$E:$E,0)-1,MATCH(AD$1,ASISTENCIA!$3:$3,0)-5,1,1) | AE6: =IF(TODAY()>=$AE$1-6,SUM(OFFSET(DEVO!$F$1,MATCH($G6,DEVO!$E:$E,0)-1,MATCH(AB$1,DEVO!$1:$1,0)-6,1,7)),"") -> 0 | AF6: =IF(TODAY()>=$AI$1-6,SUM(OFFSET(ASISTENCIA!$E$1,MATCH($G6,ASISTENCIA!$E:$E,0)-1,MATCH(AF$1,ASISTENCIA!$3:$3,0)-5,1,1)),"") -> 0 | AG6: =OFFSET(ASISTENCIA!$E$1,MATCH($G6,ASISTENCIA!$E:$E,0)-1,MATCH(AG$1,ASISTENCIA!$3:$3,0)-5,1,1) | AH6: =OFFSET(ASISTENCIA!$E$1,MATCH($G6,ASISTENCIA!$E:$E,0)-1,MATCH(AH$1,ASISTENCIA!$3:$3,0)-5,1,1) | AI6: =IF(TODAY()>=$AI$1-6,SUM(OFFSET(DEVO!$F$1,MATCH($G6,DEVO!$E:$E,0)-1,MATCH(AF$1,DEVO!$1:$1,0)-6,1,7)),"") -> 0 | AJ6: =IF(TODAY()>=$AM$1-6,SUM(OFFSET(ASISTENCIA!$E$1,MATCH($G6,ASISTENCIA!$E:$E,0)-1,MATCH(AJ$1,ASISTENCIA!$3:$3,0)-5,1,1)),"") -> 0 | AK6: =OFFSET(ASISTENCIA!$E$1,MATCH($G6,ASISTENCIA!$E:$E,0)-1,MATCH(AK$1,ASISTENCIA!$3:$3,0)-5,1,1) | AL6: =OFFSET(ASISTENCIA!$E$1,MATCH($G6,ASISTENCIA!$E:$E,0)-1,MATCH(AL$1,ASISTENCIA!$3:$3,0)-5,1,1) | AM6: =IF(TODAY()>=$AM$1-6,SUM(OFFSET(DEVO!$F$1,MATCH($G6,DEVO!$E:$E,0)-1,MATCH(AJ$1,DEVO!$1:$1,0)-6,1,7)),"") -> 0 | AN6: =IF(TODAY()>=$AQ$1-6,SUM(OFFSET(ASISTENCIA!$E$1,MATCH($G6,ASISTENCIA!$E:$E,0)-1,MATCH(AN$1,ASISTENCIA!$3:$3,0)-5,1,1)),"") -> 0 | AO6: =OFFSET(ASISTENCIA!$E$1,MATCH($G6,ASISTENCIA!$E:$E,0)-1,MATCH(AO$1,ASISTENCIA!$3:$3,0)-5,1,1) | AP6: =OFFSET(ASISTENCIA!$E$1,MATCH($G6,ASISTENCIA!$E:$E,0)-1,MATCH(AP$1,ASISTENCIA!$3:$3,0)-5,1,1) | AQ6: =IF(TODAY()>=$AQ$1-6,SUM(OFFSET(DEVO!$F$1,MATCH($G6,DEVO!$E:$E,0)-1,MATCH(AN$1,DEVO!$1:$1,0)-6,1,7)),"") -> 0 | AR6: =IF(TODAY()>=$AU$1-6,SUM(OFFSET(ASISTENCIA!$E$1,MATCH($G6,ASISTENCIA!$E:$E,0)-1,MATCH(AR$1,ASISTENCIA!$3:$3,0)-5,1,1)),"") -> 0 | AS6: =OFFSET(ASISTENCIA!$E$1,MATCH($G6,ASISTENCIA!$E:$E,0)-1,MATCH(AS$1,ASISTENCIA!$3:$3,0)-5,1,1) | AT6: =OFFSET(ASISTENCIA!$E$1,MATCH($G6,ASISTENCIA!$E:$E,0)-1,MATCH(AT$1,ASISTENCIA!$3:$3,0)-5,1,1) | AU6: =IF(TODAY()>=$AU$1-6,SUM(OFFSET(DEVO!$F$1,MATCH($G6,DEVO!$E:$E,0)-1,MATCH(AR$1,DEVO!$1:$1,0)-6,1,7)),"") -> 0 | AV6: =OFFSET(ASISTENCIA!$E$1,MATCH($G6,ASISTENCIA!$E:$E,0)-1,MATCH(AV$1,ASISTENCIA!$3:$3,0)-5,1,1) | AW6: =OFFSET(ASISTENCIA!$E$1,MATCH($G6,ASISTENCIA!$E:$E,0)-1,MATCH(AW$1,ASISTENCIA!$3:$3,0)-5,1,1) | AY6: =IF(TODAY()>=$O$1-6,COUNTIF(L6,">"&0)," ") -> 0 | AZ6: =IF(TODAY()>=$S$1-6,COUNTIF(P6,">"&0)," ") -> 0 | BA6: =IF(TODAY()>=$W$1-6,COUNTIF(T6,">"&0)," ") -> 0 | BB6: =IF(TODAY()>=$AA$1-6,COUNTIF(X6,">"&0)," ") -> 0 | BC6: =IF(TODAY()>=$AE$1-6,COUNTIF(AB6,">"&0)," ") -> 0 | BD6: =IF(TODAY()>=$AI$1-6,COUNTIF(AF6,">"&0)," ") -> 0 | BE6: =IF(TODAY()>=$AM$1-6,COUNTIF(AJ6,">"&0)," ") -> 0 | BF6: =IF(TODAY()>=$AQ$1-6,COUNTIF(AN6,">"&0)," ") -> 0 | BG6: =IF(TODAY()>=$AU$1-6,COUNTIF(AR6,">"&0)," ") -> 0 | BH6: =IFERROR(SUM(AY6:BG6)/$BJ$2,0)*10 -> 0 | BI6: =VLOOKUP(BH6,$BX$4:$BY$11,2,1) -> OBSERVADOS | BJ6: =IF(TODAY()>=$O$1-6,VLOOKUP(10*SUMPRODUCT($BJ$1:$BM$1,L6:O6)/MIN((TODAY()-$O$1+7),7),$BX$15:$BY$22,2,1)," ") -> OBSERVADOS | BK6: =IF(TODAY()>=$S$1-6,VLOOKUP(10*SUMPRODUCT($BJ$1:$BM$1,P6:S6)/MIN((TODAY()-$S$1+7),7),$BX$15:$BY$22,2,1)," ") -> OBSERVADOS | BL6: =IF(TODAY()>=$W$1-6,VLOOKUP(10*SUMPRODUCT($BJ$1:$BM$1,T6:W6)/MIN((TODAY()-$W$1+7),7),$BX$15:$BY$22,2,1)," ") -> OBSERVADOS | BM6: =IF(TODAY()>=$AA$1-6,VLOOKUP(10*SUMPRODUCT($BJ$1:$BM$1,X6:AA6)/MIN((TODAY()-$AA$1+7),7),$BX$15:$BY$22,2,1)," ") -> OBSERVADOS | BN6: =IF(TODAY()>=$AE$1-6,VLOOKUP(10*SUMPRODUCT($BJ$1:$BM$1,AB6:AE6)/MIN((TODAY()-$AE$1+7),7),$BX$15:$BY$22,2,1)," ") -> OBSERVADOS | BO6: =IF(TODAY()>=$AI$1-6,VLOOKUP(10*SUMPRODUCT($BJ$1:$BM$1,AF6:AI6)/MIN((TODAY()-$AI$1+7),7),$BX$15:$BY$22,2,1)," ") -> OBSERVADOS | BP6: =IF(TODAY()>=$AM$1-6,VLOOKUP(10*SUMPRODUCT($BJ$1:$BM$1,AJ6:AM6)/MIN((TODAY()-$AM$1+7),7),$BX$15:$BY$22,2,1)," ") -> OBSERVADOS | BQ6: =IF(TODAY()>=$AQ$1-6,VLOOKUP(10*SUMPRODUCT($BJ$1:$BM$1,AN6:AQ6)/MIN((TODAY()-$AQ$1+7),7),$BX$15:$BY$22,2,1)," ") -> OBSERVADOS | BR6: =IF(TODAY()>=$AU$1-6,VLOOKUP(10*SUMPRODUCT($BJ$1:$BM$1,AR6:AU6)/MIN((TODAY()-$AU$1+7),7),$BX$15:$BY$22,2,1)," ") -> OBSERVADOS | BS6: =OFFSET(ASISTENCIA!$E$1,MATCH($G6,ASISTENCIA!$E:$E,0)-1,MATCH(BS$1,ASISTENCIA!$3:$3,0)-5,1,1) -> Se converso con su lider , dijo que el alumno está apoyando a su esposa enferma | BT6: =OFFSET(ASISTENCIA!$E$1,MATCH($G6,ASISTENCIA!$E:$E,0)-1,MATCH(BT$1,ASISTENCIA!$3:$3,0)-5,1,1) -> Edwin Montano | BU6: =OFFSET(ASISTENCIA!$E$1,MATCH($G6,ASISTENCIA!$E:$E,0)-1,MATCH(BU$1,ASISTENCIA!$3:$3,0)-5,1,1) -> 989039557 | BV6: =OFFSET(ASISTENCIA!$E$1,MATCH($G6,ASISTENCIA!$E:$E,0)-1,MATCH(BV$1,ASISTENCIA!$3:$3,0)-5,1,1) | BX6: =IFERROR(__xludf.DUMMYFUNCTION("""COMPUTED_VALUE"""),6.121111111111111) -> 6.1211111 | BY6: =IFERROR(__xludf.DUMMYFUNCTION("""COMPUTED_VALUE"""),"REGULARES") -> REGULARES
A7: =1+A6 -> 4 | B7: =IFERROR(__xludf.DUMMYFUNCTION("""COMPUTED_VALUE"""),"ANTIOQUIANOS") -> ANTIOQUIANOS | C7: =IFERROR(__xludf.DUMMYFUNCTION("""COMPUTED_VALUE"""),"AUDI ESTELA SAHUANAY HUISACAYNA") -> AUDI ESTELA SAHUANAY HUISACAYNA | D7: =IFERROR(__xludf.DUMMYFUNCTION("""COMPUTED_VALUE"""),"ESC.LID-0227") -> ESC.LID-0227 | E7: =IFERROR(__xludf.DUMMYFUNCTION("""COMPUTED_VALUE"""),"C213F") -> C213F | F7: =IFERROR(__xludf.DUMMYFUNCTION("""COMPUTED_VALUE"""),"COMENTERO CARREÑO, MAYLY") -> COMENTERO CARREÑO, MAYLY | G7: =IFERROR(__xludf.DUMMYFUNCTION("""COMPUTED_VALUE"""),"76057551") -> 76057551 | H7: =IFERROR(__xludf.DUMMYFUNCTION("""COMPUTED_VALUE"""),"903410536") -> 903410536 | J7: =DEVO!F8 -> 38334 | K7: =IF(I7>0,I7,J7) -> 38334 | L7: =IF(TODAY()>=$O$1-6,SUM(OFFSET(ASISTENCIA!$E$1,MATCH($G7,ASISTENCIA!$E:$E,0)-1,MATCH(L$1,ASISTENCIA!$3:$3,0)-5,1,1)),"") -> 1 | M7: =OFFSET(ASISTENCIA!$E$1,MATCH($G7,ASISTENCIA!$E:$E,0)-1,MATCH(M$1,ASISTENCIA!$3:$3,0)-5,1,1) | N7: =OFFSET(ASISTENCIA!$E$1,MATCH($G7,ASISTENCIA!$E:$E,0)-1,MATCH(N$1,ASISTENCIA!$3:$3,0)-5,1,1) | O7: =IF(TODAY()>=$O$1-6,SUM(OFFSET(DEVO!$F$1,MATCH($G7,DEVO!$E:$E,0)-1,MATCH(L$1,DEVO!$1:$1,0)-6,1,7)),"") -> 0 | P7: =IF(TODAY()>=$S$1-6,SUM(OFFSET(ASISTENCIA!$E$1,MATCH($G7,ASISTENCIA!$E:$E,0)-1,MATCH(P$1,ASISTENCIA!$3:$3,0)-5,1,1)),"") -> 4 | Q7: =OFFSET(ASISTENCIA!$E$1,MATCH($G7,ASISTENCIA!$E:$E,0)-1,MATCH(Q$1,ASISTENCIA!$3:$3,0)-5,1,1) | R7: =OFFSET(ASISTENCIA!$E$1,MATCH($G7,ASISTENCIA!$E:$E,0)-1,MATCH(R$1,ASISTENCIA!$3:$3,0)-5,1,1) -> 1 | S7: =IF(TODAY()>=$S$1-6,SUM(OFFSET(DEVO!$F$1,MATCH($G7,DEVO!$E:$E,0)-1,MATCH(P$1,DEVO!$1:$1,0)-6,1,7)),"") -> 0 | T7: =IF(TODAY()>=$W$1-6,SUM(OFFSET(ASISTENCIA!$E$1,MATCH($G7,ASISTENCIA!$E:$E,0)-1,MATCH(T$1,ASISTENCIA!$3:$3,0)-5,1,1)),"") -> 3 | U7: =OFFSET(ASISTENCIA!$E$1,MATCH($G7,ASISTENCIA!$E:$E,0)-1,MATCH(U$1,ASISTENCIA!$3:$3,0)-5,1,1) | V7: =OFFSET(ASISTENCIA!$E$1,MATCH($G7,ASISTENCIA!$E:$E,0)-1,MATCH(V$1,ASISTENCIA!$3:$3,0)-5,1,1) | W7: =IF(TODAY()>=$W$1-6,SUM(OFFSET(DEVO!$F$1,MATCH($G7,DEVO!$E:$E,0)-1,MATCH(T$1,DEVO!$1:$1,0)-6,1,7)),"") -> 0 | X7: =IF(TODAY()>=$AA$1-6,SUM(OFFSET(ASISTENCIA!$E$1,MATCH($G7,ASISTENCIA!$E:$E,0)-1,MATCH(X$1,ASISTENCIA!$3:$3,0)-5,1,1)),"") -> 1 | Y7: =OFFSET(ASISTENCIA!$E$1,MATCH($G7,ASISTENCIA!$E:$E,0)-1,MATCH(Y$1,ASISTENCIA!$3:$3,0)-5,1,1) | Z7: =OFFSET(ASISTENCIA!$E$1,MATCH($G7,ASISTENCIA!$E:$E,0)-1,MATCH(Z$1,ASISTENCIA!$3:$3,0)-5,1,1) -> 1 | AA7: =IF(TODAY()>=$AA$1-6,SUM(OFFSET(DEVO!$F$1,MATCH($G7,DEVO!$E:$E,0)-1,MATCH(X$1,DEVO!$1:$1,0)-6,1,7)),"") -> 0 | AB7: =IF(TODAY()>=$AE$1-6,SUM(OFFSET(ASISTENCIA!$E$1,MATCH($G7,ASISTENCIA!$E:$E,0)-1,MATCH(AB$1,ASISTENCIA!$3:$3,0)-5,1,1)),"") -> 3 | AC7: =OFFSET(ASISTENCIA!$E$1,MATCH($G7,ASISTENCIA!$E:$E,0)-1,MATCH(AC$1,ASISTENCIA!$3:$3,0)-5,1,1) | AD7: =OFFSET(ASISTENCIA!$E$1,MATCH($G7,ASISTENCIA!$E:$E,0)-1,MATCH(AD$1,ASISTENCIA!$3:$3,0)-5,1,1) -> 1 | AE7: =IF(TODAY()>=$AE$1-6,SUM(OFFSET(DEVO!$F$1,MATCH($G7,DEVO!$E:$E,0)-1,MATCH(AB$1,DEVO!$1:$1,0)-6,1,7)),"") -> 0 | AF7: =IF(TODAY()>=$AI$1-6,SUM(OFFSET(ASISTENCIA!$E$1,MATCH($G7,ASISTENCIA!$E:$E,0)-1,MATCH(AF$1,ASISTENCIA!$3:$3,0)-5,1,1)),"") -> 1 | AG7: =OFFSET(ASISTENCIA!$E$1,MATCH($G7,ASISTENCIA!$E:$E,0)-1,MATCH(AG$1,ASISTENCIA!$3:$3,0)-5,1,1) | AH7: =OFFSET(ASISTENCIA!$E$1,MATCH($G7,ASISTENCIA!$E:$E,0)-1,MATCH(AH$1,ASISTENCIA!$3:$3,0)-5,1,1) -> 1 | AI7: =IF(TODAY()>=$AI$1-6,SUM(OFFSET(DEVO!$F$1,MATCH($G7,DEVO!$E:$E,0)-1,MATCH(AF$1,DEVO!$1:$1,0)-6,1,7)),"") -> 0 | AJ7: =IF(TODAY()>=$AM$1-6,SUM(OFFSET(ASISTENCIA!$E$1,MATCH($G7,ASISTENCIA!$E:$E,0)-1,MATCH(AJ$1,ASISTENCIA!$3:$3,0)-5,1,1)),"") -> 1 | AK7: =OFFSET(ASISTENCIA!$E$1,MATCH($G7,ASISTENCIA!$E:$E,0)-1,MATCH(AK$1,ASISTENCIA!$3:$3,0)-5,1,1) | AL7: =OFFSET(ASISTENCIA!$E$1,MATCH($G7,ASISTENCIA!$E:$E,0)-1,MATCH(AL$1,ASISTENCIA!$3:$3,0)-5,1,1) -> 1 | AM7: =IF(TODAY()>=$AM$1-6,SUM(OFFSET(DEVO!$F$1,MATCH($G7,DEVO!$E:$E,0)-1,MATCH(AJ$1,DEVO!$1:$1,0)-6,1,7)),"") -> 0 | AN7: =IF(TODAY()>=$AQ$1-6,SUM(OFFSET(ASISTENCIA!$E$1,MATCH($G7,ASISTENCIA!$E:$E,0)-1,MATCH(AN$1,ASISTENCIA!$3:$3,0)-5,1,1)),"") -> 2 | AO7: =OFFSET(ASISTENCIA!$E$1,MATCH($G7,ASISTENCIA!$E:$E,0)-1,MATCH(AO$1,ASISTENCIA!$3:$3,0)-5,1,1) | AP7: =OFFSET(ASISTENCIA!$E$1,MATCH($G7,ASISTENCIA!$E:$E,0)-1,MATCH(AP$1,ASISTENCIA!$3:$3,0)-5,1,1) -> 1 | AQ7: =IF(TODAY()>=$AQ$1-6,SUM(OFFSET(DEVO!$F$1,MATCH($G7,DEVO!$E:$E,0)-1,MATCH(AN$1,DEVO!$1:$1,0)-6,1,7)),"") -> 0 | AR7: =IF(TODAY()>=$AU$1-6,SUM(OFFSET(ASISTENCIA!$E$1,MATCH($G7,ASISTENCIA!$E:$E,0)-1,MATCH(AR$1,ASISTENCIA!$3:$3,0)-5,1,1)),"") -> 2 | AS7: =OFFSET(ASISTENCIA!$E$1,MATCH($G7,ASISTENCIA!$E:$E,0)-1,MATCH(AS$1,ASISTENCIA!$3:$3,0)-5,1,1) | AT7: =OFFSET(ASISTENCIA!$E$1,MATCH($G7,ASISTENCIA!$E:$E,0)-1,MATCH(AT$1,ASISTENCIA!$3:$3,0)-5,1,1) -> 1 | AU7: =IF(TODAY()>=$AU$1-6,SUM(OFFSET(DEVO!$F$1,MATCH($G7,DEVO!$E:$E,0)-1,MATCH(AR$1,DEVO!$1:$1,0)-6,1,7)),"") -> 0 | AV7: =OFFSET(ASISTENCIA!$E$1,MATCH($G7,ASISTENCIA!$E:$E,0)-1,MATCH(AV$1,ASISTENCIA!$3:$3,0)-5,1,1) -> 0 | AW7: =OFFSET(ASISTENCIA!$E$1,MATCH($G7,ASISTENCIA!$E:$E,0)-1,MATCH(AW$1,ASISTENCIA!$3:$3,0)-5,1,1) -> 20 | AY7: =IF(TODAY()>=$O$1-6,COUNTIF(L7,">"&0)," ") -> 1 | AZ7: =IF(TODAY()>=$S$1-6,COUNTIF(P7,">"&0)," ") -> 1 | BA7: =IF(TODAY()>=$W$1-6,COUNTIF(T7,">"&0)," ") -> 1 | BB7: =IF(TODAY()>=$AA$1-6,COUNTIF(X7,">"&0)," ") -> 1 | BC7: =IF(TODAY()>=$AE$1-6,COUNTIF(AB7,">"&0)," ") -> 1 | BD7: =IF(TODAY()>=$AI$1-6,COUNTIF(AF7,">"&0)," ") -> 1 | BE7: =IF(TODAY()>=$AM$1-6,COUNTIF(AJ7,">"&0)," ") -> 1 | BF7: =IF(TODAY()>=$AQ$1-6,COUNTIF(AN7,">"&0)," ") -> 1 | BG7: =IF(TODAY()>=$AU$1-6,COUNTIF(AR7,">"&0)," ") -> 1 | BH7: =IFERROR(SUM(AY7:BG7)/$BJ$2,0)*10 -> 10 | BI7: =VLOOKUP(BH7,$BX$4:$BY$11,2,1) -> EXCELENTES | BJ7: =IF(TODAY()>=$O$1-6,VLOOKUP(10*SUMPRODUCT($BJ$1:$BM$1,L7:O7)/MIN((TODAY()-$O$1+7),7),$BX$15:$BY$22,2,1)," ") -> OBSERVADOS | BK7: =IF(TODAY()>=$S$1-6,VLOOKUP(10*SUMPRODUCT($BJ$1:$BM$1,P7:S7)/MIN((TODAY()-$S$1+7),7),$BX$15:$BY$22,2,1)," ") -> OBSERVADOS | BL7: =IF(TODAY()>=$W$1-6,VLOOKUP(10*SUMPRODUCT($BJ$1:$BM$1,T7:W7)/MIN((TODAY()-$W$1+7),7),$BX$15:$BY$22,2,1)," ") -> OBSERVADOS | BM7: =IF(TODAY()>=$AA$1-6,VLOOKUP(10*SUMPRODUCT($BJ$1:$BM$1,X7:AA7)/MIN((TODAY()-$AA$1+7),7),$BX$15:$BY$22,2,1)," ") -> OBSERVADOS | BN7: =IF(TODAY()>=$AE$1-6,VLOOKUP(10*SUMPRODUCT($BJ$1:$BM$1,AB7:AE7)/MIN((TODAY()-$AE$1+7),7),$BX$15:$BY$22,2,1)," ") -> OBSERVADOS | BO7: =IF(TODAY()>=$AI$1-6,VLOOKUP(10*SUMPRODUCT($BJ$1:$BM$1,AF7:AI7)/MIN((TODAY()-$AI$1+7),7),$BX$15:$BY$22,2,1)," ") -> OBSERVADOS | BP7: =IF(TODAY()>=$AM$1-6,VLOOKUP(10*SUMPRODUCT($BJ$1:$BM$1,AJ7:AM7)/MIN((TODAY()-$AM$1+7),7),$BX$15:$BY$22,2,1)," ") -> OBSERVADOS | BQ7: =IF(TODAY()>=$AQ$1-6,VLOOKUP(10*SUMPRODUCT($BJ$1:$BM$1,AN7:AQ7)/MIN((TODAY()-$AQ$1+7),7),$BX$15:$BY$22,2,1)," ") -> OBSERVADOS | BR7: =IF(TODAY()>=$AU$1-6,VLOOKUP(10*SUMPRODUCT($BJ$1:$BM$1,AR7:AU7)/MIN((TODAY()-$AU$1+7),7),$BX$15:$BY$22,2,1)," ") -> OBSERVADOS | BS7: =OFFSET(ASISTENCIA!$E$1,MATCH($G7,ASISTENCIA!$E:$E,0)-1,MATCH(BS$1,ASISTENCIA!$3:$3,0)-5,1,1) -> El trabajo no es del libro, ni un libro cristiano, ni una apreciación de clase. | BT7: =OFFSET(ASISTENCIA!$E$1,MATCH($G7,ASISTENCIA!$E:$E,0)-1,MATCH(BT$1,ASISTENCIA!$3:$3,0)-5,1,1) -> Miriam | BU7: =OFFSET(ASISTENCIA!$E$1,MATCH($G7,ASISTENCIA!$E:$E,0)-1,MATCH(BU$1,ASISTENCIA!$3:$3,0)-5,1,1) -> 976312280 | BV7: =OFFSET(ASISTENCIA!$E$1,MATCH($G7,ASISTENCIA!$E:$E,0)-1,MATCH(BV$1,ASISTENCIA!$3:$3,0)-5,1,1) | BX7: =IFERROR(__xludf.DUMMYFUNCTION("""COMPUTED_VALUE"""),8.333333333333334) -> 8.3333333 | BY7: =IFERROR(__xludf.DUMMYFUNCTION("""COMPUTED_VALUE"""),"REGULARES") -> REGULARES
A8: =1+A7 -> 5 | B8: =IFERROR(__xludf.DUMMYFUNCTION("""COMPUTED_VALUE"""),"ANTIOQUIANOS") -> ANTIOQUIANOS | C8: =IFERROR(__xludf.DUMMYFUNCTION("""COMPUTED_VALUE"""),"AUDI ESTELA SAHUANAY HUISACAYNA") -> AUDI ESTELA SAHUANAY HUISACAYNA | D8: =IFERROR(__xludf.DUMMYFUNCTION("""COMPUTED_VALUE"""),"ESC.LID-0233") -> ESC.LID-0233 | E8: =IFERROR(__xludf.DUMMYFUNCTION("""COMPUTED_VALUE"""),"C1133") -> C1133 | F8: =IFERROR(__xludf.DUMMYFUNCTION("""COMPUTED_VALUE"""),"ECHEVARRIA LINARES, EDISON EDWARD’S") -> ECHEVARRIA LINARES, EDISON EDWARD’S | G8: =IFERROR(__xludf.DUMMYFUNCTION("""COMPUTED_VALUE"""),"73683815") -> 73683815 | H8: =IFERROR(__xludf.DUMMYFUNCTION("""COMPUTED_VALUE"""),"907512087") -> 907512087 | J8: =DEVO!F9 -> 34217 | K8: =IF(I8>0,I8,J8) -> 34217 | L8: =IF(TODAY()>=$O$1-6,SUM(OFFSET(ASISTENCIA!$E$1,MATCH($G8,ASISTENCIA!$E:$E,0)-1,MATCH(L$1,ASISTENCIA!$3:$3,0)-5,1,1)),"") -> 1 | M8: =OFFSET(ASISTENCIA!$E$1,MATCH($G8,ASISTENCIA!$E:$E,0)-1,MATCH(M$1,ASISTENCIA!$3:$3,0)-5,1,1) | N8: =OFFSET(ASISTENCIA!$E$1,MATCH($G8,ASISTENCIA!$E:$E,0)-1,MATCH(N$1,ASISTENCIA!$3:$3,0)-5,1,1) | O8: =IF(TODAY()>=$O$1-6,SUM(OFFSET(DEVO!$F$1,MATCH($G8,DEVO!$E:$E,0)-1,MATCH(L$1,DEVO!$1:$1,0)-6,1,7)),"") -> 4 | P8: =IF(TODAY()>=$S$1-6,SUM(OFFSET(ASISTENCIA!$E$1,MATCH($G8,ASISTENCIA!$E:$E,0)-1,MATCH(P$1,ASISTENCIA!$3:$3,0)-5,1,1)),"") -> 1 | Q8: =OFFSET(ASISTENCIA!$E$1,MATCH($G8,ASISTENCIA!$E:$E,0)-1,MATCH(Q$1,ASISTENCIA!$3:$3,0)-5,1,1) | R8: =OFFSET(ASISTENCIA!$E$1,MATCH($G8,ASISTENCIA!$E:$E,0)-1,MATCH(R$1,ASISTENCIA!$3:$3,0)-5,1,1) -> 1 | S8: =IF(TODAY()>=$S$1-6,SUM(OFFSET(DEVO!$F$1,MATCH($G8,DEVO!$E:$E,0)-1,MATCH(P$1,DEVO!$1:$1,0)-6,1,7)),"") -> 7 | T8: =IF(TODAY()>=$W$1-6,SUM(OFFSET(ASISTENCIA!$E$1,MATCH($G8,ASISTENCIA!$E:$E,0)-1,MATCH(T$1,ASISTENCIA!$3:$3,0)-5,1,1)),"") -> 0 | U8: =OFFSET(ASISTENCIA!$E$1,MATCH($G8,ASISTENCIA!$E:$E,0)-1,MATCH(U$1,ASISTENCIA!$3:$3,0)-5,1,1) | V8: =OFFSET(ASISTENCIA!$E$1,MATCH($G8,ASISTENCIA!$E:$E,0)-1,MATCH(V$1,ASISTENCIA!$3:$3,0)-5,1,1) | W8: =IF(TODAY()>=$W$1-6,SUM(OFFSET(DEVO!$F$1,MATCH($G8,DEVO!$E:$E,0)-1,MATCH(T$1,DEVO!$1:$1,0)-6,1,7)),"") -> 7 | X8: =IF(TODAY()>=$AA$1-6,SUM(OFFSET(ASISTENCIA!$E$1,MATCH($G8,ASISTENCIA!$E:$E,0)-1,MATCH(X$1,ASISTENCIA!$3:$3,0)-5,1,1)),"") -> 1 | Y8: =OFFSET(ASISTENCIA!$E$1,MATCH($G8,ASISTENCIA!$E:$E,0)-1,MATCH(Y$1,ASISTENCIA!$3:$3,0)-5,1,1) | Z8: =OFFSET(ASISTENCIA!$E$1,MATCH($G8,ASISTENCIA!$E:$E,0)-1,MATCH(Z$1,ASISTENCIA!$3:$3,0)-5,1,1) | AA8: =IF(TODAY()>=$AA$1-6,SUM(OFFSET(DEVO!$F$1,MATCH($G8,DEVO!$E:$E,0)-1,MATCH(X$1,DEVO!$1:$1,0)-6,1,7)),"") -> 7 | AB8: =IF(TODAY()>=$AE$1-6,SUM(OFFSET(ASISTENCIA!$E$1,MATCH($G8,ASISTENCIA!$E:$E,0)-1,MATCH(AB$1,ASISTENCIA!$3:$3,0)-5,1,1)),"") -> 2 | AC8: =OFFSET(ASISTENCIA!$E$1,MATCH($G8,ASISTENCIA!$E:$E,0)-1,MATCH(AC$1,ASISTENCIA!$3:$3,0)-5,1,1) | AD8: =OFFSET(ASISTENCIA!$E$1,MATCH($G8,ASISTENCIA!$E:$E,0)-1,MATCH(AD$1,ASISTENCIA!$3:$3,0)-5,1,1) | AE8: =IF(TODAY()>=$AE$1-6,SUM(OFFSET(DEVO!$F$1,MATCH($G8,DEVO!$E:$E,0)-1,MATCH(AB$1,DEVO!$1:$1,0)-6,1,7)),"") -> 0 | AF8: =IF(TODAY()>=$AI$1-6,SUM(OFFSET(ASISTENCIA!$E$1,MATCH($G8,ASISTENCIA!$E:$E,0)-1,MATCH(AF$1,ASISTENCIA!$3:$3,0)-5,1,1)),"") -> 1 | AG8: =OFFSET(ASISTENCIA!$E$1,MATCH($G8,ASISTENCIA!$E:$E,0)-1,MATCH(AG$1,ASISTENCIA!$3:$3,0)-5,1,1) | AH8: =OFFSET(ASISTENCIA!$E$1,MATCH($G8,ASISTENCIA!$E:$E,0)-1,MATCH(AH$1,ASISTENCIA!$3:$3,0)-5,1,1) | AI8: =IF(TODAY()>=$AI$1-6,SUM(OFFSET(DEVO!$F$1,MATCH($G8,DEVO!$E:$E,0)-1,MATCH(AF$1,DEVO!$1:$1,0)-6,1,7)),"") -> 7 | AJ8: =IF(TODAY()>=$AM$1-6,SUM(OFFSET(ASISTENCIA!$E$1,MATCH($G8,ASISTENCIA!$E:$E,0)-1,MATCH(AJ$1,ASISTENCIA!$3:$3,0)-5,1,1)),"") -> 1 | AK8: =OFFSET(ASISTENCIA!$E$1,MATCH($G8,ASISTENCIA!$E:$E,0)-1,MATCH(AK$1,ASISTENCIA!$3:$3,0)-5,1,1) | AL8: =OFFSET(ASISTENCIA!$E$1,MATCH($G8,ASISTENCIA!$E:$E,0)-1,MATCH(AL$1,ASISTENCIA!$3:$3,0)-5,1,1) | AM8: =IF(TODAY()>=$AM$1-6,SUM(OFFSET(DEVO!$F$1,MATCH($G8,DEVO!$E:$E,0)-1,MATCH(AJ$1,DEVO!$1:$1,0)-6,1,7)),"") -> 7 | AN8: =IF(TODAY()>=$AQ$1-6,SUM(OFFSET(ASISTENCIA!$E$1,MATCH($G8,ASISTENCIA!$E:$E,0)-1,MATCH(AN$1,ASISTENCIA!$3:$3,0)-5,1,1)),"") -> 1 | AO8: =OFFSET(ASISTENCIA!$E$1,MATCH($G8,ASISTENCIA!$E:$E,0)-1,MATCH(AO$1,ASISTENCIA!$3:$3,0)-5,1,1) | AP8: =OFFSET(ASISTENCIA!$E$1,MATCH($G8,ASISTENCIA!$E:$E,0)-1,MATCH(AP$1,ASISTENCIA!$3:$3,0)-5,1,1) -> 1 | AQ8: =IF(TODAY()>=$AQ$1-6,SUM(OFFSET(DEVO!$F$1,MATCH($G8,DEVO!$E:$E,0)-1,MATCH(AN$1,DEVO!$1:$1,0)-6,1,7)),"") -> 0 | AR8: =IF(TODAY()>=$AU$1-6,SUM(OFFSET(ASISTENCIA!$E$1,MATCH($G8,ASISTENCIA!$E:$E,0)-1,MATCH(AR$1,ASISTENCIA!$3:$3,0)-5,1,1)),"") -> 2 | AS8: =OFFSET(ASISTENCIA!$E$1,MATCH($G8,ASISTENCIA!$E:$E,0)-1,MATCH(AS$1,ASISTENCIA!$3:$3,0)-5,1,1) | AT8: =OFFSET(ASISTENCIA!$E$1,MATCH($G8,ASISTENCIA!$E:$E,0)-1,MATCH(AT$1,ASISTENCIA!$3:$3,0)-5,1,1) -> 1 | AU8: =IF(TODAY()>=$AU$1-6,SUM(OFFSET(DEVO!$F$1,MATCH($G8,DEVO!$E:$E,0)-1,MATCH(AR$1,DEVO!$1:$1,0)-6,1,7)),"") -> 0 | AV8: =OFFSET(ASISTENCIA!$E$1,MATCH($G8,ASISTENCIA!$E:$E,0)-1,MATCH(AV$1,ASISTENCIA!$3:$3,0)-5,1,1) -> 13 | AW8: =OFFSET(ASISTENCIA!$E$1,MATCH($G8,ASISTENCIA!$E:$E,0)-1,MATCH(AW$1,ASISTENCIA!$3:$3,0)-5,1,1) -> 20 | AY8: =IF(TODAY()>=$O$1-6,COUNTIF(L8,">"&0)," ") -> 1 | AZ8: =IF(TODAY()>=$S$1-6,COUNTIF(P8,">"&0)," ") -> 1 | BA8: =IF(TODAY()>=$W$1-6,COUNTIF(T8,">"&0)," ") -> 0 | BB8: =IF(TODAY()>=$AA$1-6,COUNTIF(X8,">"&0)," ") -> 1 | BC8: =IF(TODAY()>=$AE$1-6,COUNTIF(AB8,">"&0)," ") -> 1 | BD8: =IF(TODAY()>=$AI$1-6,COUNTIF(AF8,">"&0)," ") -> 1 | BE8: =IF(TODAY()>=$AM$1-6,COUNTIF(AJ8,">"&0)," ") -> 1 | BF8: =IF(TODAY()>=$AQ$1-6,COUNTIF(AN8,">"&0)," ") -> 1 | BG8: =IF(TODAY()>=$AU$1-6,COUNTIF(AR8,">"&0)," ") -> 1 | BH8: =IFERROR(SUM(AY8:BG8)/$BJ$2,0)*10 -> 8.8888889 | BI8: =VLOOKUP(BH8,$BX$4:$BY$11,2,1) -> BUENO | BJ8: =IF(TODAY()>=$O$1-6,VLOOKUP(10*SUMPRODUCT($BJ$1:$BM$1,L8:O8)/MIN((TODAY()-$O$1+7),7),$BX$15:$BY$22,2,1)," ") -> REGULARES | BK8: =IF(TODAY()>=$S$1-6,VLOOKUP(10*SUMPRODUCT($BJ$1:$BM$1,P8:S8)/MIN((TODAY()-$S$1+7),7),$BX$15:$BY$22,2,1)," ") -> EXCELENTES | BL8: =IF(TODAY()>=$W$1-6,VLOOKUP(10*SUMPRODUCT($BJ$1:$BM$1,T8:W8)/MIN((TODAY()-$W$1+7),7),$BX$15:$BY$22,2,1)," ") -> EXCELENTES | BM8: =IF(TODAY()>=$AA$1-6,VLOOKUP(10*SUMPRODUCT($BJ$1:$BM$1,X8:AA8)/MIN((TODAY()-$AA$1+7),7),$BX$15:$BY$22,2,1)," ") -> EXCELENTES | BN8: =IF(TODAY()>=$AE$1-6,VLOOKUP(10*SUMPRODUCT($BJ$1:$BM$1,AB8:AE8)/MIN((TODAY()-$AE$1+7),7),$BX$15:$BY$22,2,1)," ") -> OBSERVADOS | BO8: =IF(TODAY()>=$AI$1-6,VLOOKUP(10*SUMPRODUCT($BJ$1:$BM$1,AF8:AI8)/MIN((TODAY()-$AI$1+7),7),$BX$15:$BY$22,2,1)," ") -> EXCELENTES | BP8: =IF(TODAY()>=$AM$1-6,VLOOKUP(10*SUMPRODUCT($BJ$1:$BM$1,AJ8:AM8)/MIN((TODAY()-$AM$1+7),7),$BX$15:$BY$22,2,1)," ") -> EXCELENTES | BQ8: =IF(TODAY()>=$AQ$1-6,VLOOKUP(10*SUMPRODUCT($BJ$1:$BM$1,AN8:AQ8)/MIN((TODAY()-$AQ$1+7),7),$BX$15:$BY$22,2,1)," ") -> OBSERVADOS | BR8: =IF(TODAY()>=$AU$1-6,VLOOKUP(10*SUMPRODUCT($BJ$1:$BM$1,AR8:AU8)/MIN((TODAY()-$AU$1+7),7),$BX$15:$BY$22,2,1)," ") -> OBSERVADOS | BS8: =OFFSET(ASISTENCIA!$E$1,MATCH($G8,ASISTENCIA!$E:$E,0)-1,MATCH(BS$1,ASISTENCIA!$3:$3,0)-5,1,1) | BT8: =OFFSET(ASISTENCIA!$E$1,MATCH($G8,ASISTENCIA!$E:$E,0)-1,MATCH(BT$1,ASISTENCIA!$3:$3,0)-5,1,1) -> William Bonifacio | BU8: =OFFSET(ASISTENCIA!$E$1,MATCH($G8,ASISTENCIA!$E:$E,0)-1,MATCH(BU$1,ASISTENCIA!$3:$3,0)-5,1,1) -> 981070518 | BV8: =OFFSET(ASISTENCIA!$E$1,MATCH($G8,ASISTENCIA!$E:$E,0)-1,MATCH(BV$1,ASISTENCIA!$3:$3,0)-5,1,1) | BX8: =IFERROR(__xludf.DUMMYFUNCTION("""COMPUTED_VALUE"""),8.343333333333334) -> 8.3433333 | BY8: =IFERROR(__xludf.DUMMYFUNCTION("""COMPUTED_VALUE"""),"BUENO") -> BUENO
